Workbook
Name นางสาว_Chen_Yang: Course_list!$A$2
Name นางสาว_Haitao_Liu: Course_list!$A$3:$A$4
Name นาย_Shengzhe_Huang: Course_list!$A$14

Sheet manual
A1: แบบใบเบิกค่าตอบแทนทุนผู้ช่วยสอน
A2: วิทยาลัยศิลปะ สื่อ และเทคโนโลยี มหาวิทยาลัยเชียงใหม่
C3: ประจำเดือน | D3: เมษายน 2569
A5: ระดับ | B5: FALSE | C5: บัณฑิตศึกษา | D5: หลักสูตร | E5: TRUE | F5: ภาคปกติ
B6: TRUE | C6: ปริญญาตรี | E6: FALSE | F6: ภาคพิเศษ
E7: FALSE | F7: นานาชาติ
A9: ชื่อผู้สอน | B9: วันเดือนปีที่สอน | C9: กระบวนวิชา | D9: จำนวนชั่วโมง | E9: ค่าสอนต่อชั่วโมง | F9: รวมค่าสอน | G9: ผู้รับเงิน | H9: หมายเหตุ
A10: นาย ธิติพันธ์ ลิ้มชวพันธนกุล | B10: 46139 | C10: 960100 | D10: 3 | E10: =IF(D10="","",200) -> 200 | F10: =IF(OR(D10="",E10=""),"",D10*E10) -> 600
A11: นาย ธิติพันธ์ ลิ้มชวพันธนกุล | B11: 46140 | C11: 960100 | D11: 5 | E11: =IF(D11="","",200) -> 200 | F11: =IF(OR(D11="",E11=""),"",D11*E11) -> 1000
A12: นาย ธิติพันธ์ ลิ้มชวพันธนกุล | B12: 46141 | C12: 960100 | D12: 5 | E12: =IF(D12="","",200) -> 200 | F12: =IF(OR(D12="",E12=""),"",D12*E12) -> 1000
A13: นาย ธิติพันธ์ ลิ้มชวพันธนกุล | B13: 46142 | C13: 960100 | D13: 5 | E13: =IF(D13="","",200) -> 200 | F13: =IF(OR(D13="",E13=""),"",D13*E13) -> 1000
A14: นาย ธิติพันธ์ ลิ้มชวพันธนกุล | B14: 46143 | C14: 960100 | D14: 5 | E14: =IF(D14="","",200) -> 200 | F14: =IF(OR(D14="",E14=""),"",D14*E14) -> 1000
A15: นาย ธิติพันธ์ ลิ้มชวพันธนกุล | B15: 46147 | C15: 960100 | D15: 4 | E15: =IF(D15="","",200) -> 200 | F15: =IF(OR(D15="",E15=""),"",D15*E15) -> 800
A16: นาย ธิติพันธ์ ลิ้มชวพันธนกุล | B16: 46148 | C16: 960100 | D16: 3 | E16: =IF(D16="","",200) -> 200 | F16: =IF(OR(D16="",E16=""),"",D16*E16) -> 600
E17: =IF(D17="","",200) | F17: =IF(OR(D17="",E17=""),"",D17*E17)
E18: =IF(D18="","",200) | F18: =IF(OR(D18="",E18=""),"",D18*E18)
E19: =IF(D19="","",200) | F19: =IF(OR(D19="",E19=""),"",D19*E19)
E20: =IF(D20="","",200) | F20: =IF(OR(D20="",E20=""),"",D20*E20)
E21: =IF(D21="","",200) | F21: =IF(OR(D21="",E21=""),"",D21*E21)
E22: =IF(D22="","",200) | F22: =IF(OR(D22="",E22=""),"",D22*E22)
E23: =IF(D23="","",200) | F23: =IF(OR(D23="",E23=""),"",D23*E23) | H23: =IF(B23="","",IF((VLOOKUP(B23,Maintable!J:L,3,FALSE))<>0,VLOOKUP(B23,Maintable!J:L,3,FALSE),""))
E24: =IF(D24="","",200) | F24: =IF(OR(D24="",E24=""),"",D24*E24) | H24: =IF(B24="","",IF((VLOOKUP(B24,Maintable!J:L,3,FALSE))<>0,VLOOKUP(B24,Maintable!J:L,3,FALSE),""))
E25: =IF(D25="","",200) | F25: =IF(OR(D25="",E25=""),"",D25*E25) | H25: =IF(B25="","",IF((VLOOKUP(B25,Maintable!J:L,3,FALSE))<>0,VLOOKUP(B25,Maintable!J:L,3,FALSE),""))
E26: =IF(D26="","",200) | F26: =IF(OR(D26="",E26=""),"",D26*E26) | H26: =IF(B26="","",IF((VLOOKUP(B26,Maintable!J:L,3,FALSE))<>0,VLOOKUP(B26,Maintable!J:L,3,FALSE),""))
E27: =IF(D27="","",200) | F27: =IF(OR(D27="",E27=""),"",D27*E27) | H27: =IF(B27="","",IF((VLOOKUP(B27,Maintable!J:L,3,FALSE))<>0,VLOOKUP(B27,Maintable!J:L,3,FALSE),""))
E28: =IF(D28="","",200) | F28: =IF(OR(D28="",E28=""),"",D28*E28) | H28: =IF(B28="","",IF((VLOOKUP(B28,Maintable!J:L,3,FALSE))<>0,VLOOKUP(B28,Maintable!J:L,3,FALSE),""))
A29: รวมจำนวนเงินที่ขอเบิก | C29: =SUM(F10:F28) -> 6000 | E29: =BAHTTEXT(C29) -> หกพันบาทถ้วน
A31: ผู้จัดทำ/ผู้ตรวจสอบ | B31: หัวหน้าภาควิชาหรือตำแหน่งอื่นที่เทียบเท่า | E31: ผู้อนุมัติ | G31: ผู้จ่ายเงิน
A32: ลงชื่อ.................................................. | B32: ลงชื่อ..................................................... | E32: ลงชื่อ..................................................... | G32: ลงชื่อ.....................................................
A33: (........................................................) | B33: (........................................................) | E33: (........................................................) | G33: (........................................................)
A34: ตำแหน่ง............................................. | B34: ตำแหน่ง................................................ | E34: ตำแหน่ง................................................ | G34: ตำแหน่ง................................................
A35: วันที่................................................... | B35: วันที่...................................................... | E35: วันที่...................................................... | G35: วันที่......................................................

Sheet Maintable
A1: Key | B1: ชื่อผู้สอน | C1: รหัสวิชา | D1: Section | E1: Rate | G1: เดือน / ปี | H1: DateID | I1: เดือนCAMT | J1: วันที่เขียนเบิกได้ | K1: ช่วงเบิกที่ | L1: หมายเหตุ | N1: UserID | O1: รายชื่อ อ.พิเศษ
A2: =C2&" "&D2 -> 955103 701 | B2: นางสาว Chen Yang | C2: 955103 | D2: 701 | E2: 300 | G2: มิถุนายน 2567 | H2: 1 | I2: มิถุนายน 2567 | J2: 45460 | K2: 1 | N2: U1 | O2: นางสาว Chen Yang
A3: =C3&" "&D3 -> 953201 701 | B3: นางสาว Haitao Liu | C3: 953201 | D3: 701 | E3: 300 | G3: กรกฎาคม 2567 | H3: 2 | I3: มิถุนายน 2567 | J3: 45461 | K3: 1 | N3: U2 | O3: นางสาว Haitao Liu
A4: =C4&" "&D4 -> 953321 701 | B4: นางสาว Haitao Liu | C4: 953321 | D4: 701 | E4: 300 | G4: สิงหาคม 2567 | H4: 3 | I4: มิถุนายน 2567 | J4: 45462 | K4: 1 | N4: U3 | O4: นางสาว เพ็ญศิริ นิจประกิจ
A5: =C5&" "&D5 -> 951312 001 | B5: นางสาว เพ็ญศิริ นิจประกิจ | C5: 951312 | D5: 001 | E5: 200 | G5: กันยายน 2567 | H5: 4 | I5: มิถุนายน 2567 | J5: 45463 | K5: 1 | N5: U4 | O5: นางสาว ธนธรณ์ ปัญญาแก้ว
A6: =C6&" "&D6 -> 958261 001 | B6: นางสาว เพ็ญศิริ นิจประกิจ | C6: 958261 | D6: 001 | E6: 200 | G6: ตุลาคม 2567 | H6: 5 | I6: มิถุนายน 2567 | J6: 45464 | K6: 1 | N6: U5 | O6: นางสาว พิมพ์ชนก กลิ่นจันทร์
A7: =C7&" "&D7 -> 958481 004 | B7: นางสาว ธนธรณ์ ปัญญาแก้ว | C7: 958481 | D7: 004 | E7: 200 | H7: 6 | I7: มิถุนายน 2567 | J7: 45465 | K7: 1 | L7: Sat. สอนตามจริง | N7: U6 | O7: นางสาว พิมพิกา สุภาวงค์
A8: =C8&" "&D8 -> 954347 001 | B8: นางสาว พิมพ์ชนก กลิ่นจันทร์ | C8: 954347 | D8: 001 | E8: 200 | H8: 7 | I8: มิถุนายน 2567 | J8: 45466 | K8: 1 | L8: Sun. สอนตามจริง | N8: U7 | O8: นางสาว ภคมณฑ์ กรสังข์
A9: =C9&" "&D9 -> 954231 002-01 | B9: นางสาว พิมพิกา สุภาวงค์ | C9: 954231 | D9: 002-01 | E9: 200 | H9: 8 | I9: มิถุนายน 2567 | J9: 45467 | K9: 1 | N9: U8 | O9: นางสาว มนัสนันท์ ขันทอง
A10: =C10&" "&D10 -> 951106 001 | B10: นางสาว ภคมณฑ์ กรสังข์ | C10: 951106 | D10: 001 | E10: 200 | H10: 9 | I10: มิถุนายน 2567 | J10: 45468 | K10: 1 | N10: U9 | O10: นางสาว วณัทชญา แก้ววงวาน
A11: =C11&" "&D11 -> 960141 001-1 | B11: นางสาว มนัสนันท์ ขันทอง | C11: 960141 | D11: 001-1 | E11: 200 | H11: 10 | I11: มิถุนายน 2567 | J11: 45469 | K11: 1 | N11: U10 | O11: นาย Shengzhe Huang
A12: =C12&" "&D12 -> 960231 001 | B12: นางสาว มนัสนันท์ ขันทอง | C12: 960231 | D12: 001 | E12: 200 | H12: 11 | I12: มิถุนายน 2567 | J12: 45470 | K12: 1 | N12: U11 | O12: นาย เกริก สุริยมณี
A13: =C13&" "&D13 -> 960331 001 | B13: นางสาว วณัทชญา แก้ววงวาน | C13: 960331 | D13: 001 | E13: 200 | H13: 12 | I13: มิถุนายน 2567 | J13: 45471 | K13: 1 | N13: U12 | O13: นาย เกริกเกียรติ วงศ์อุทัย
A14: =C14&" "&D14 -> 953212 703 | B14: นาย Shengzhe Huang | C14: 953212 | D14: 703 | E14: 300 | H14: 13 | I14: มิถุนายน 2567 | J14: 45472 | K14: 1 | L14: Sat. สอนตามจริง | N14: U13 | O14: นาย เตชณัฐ อัครจาคะ
A15: =C15&" "&D15 -> 954231 001-01 | B15: นาย เกริก สุริยมณี | C15: 954231 | D15: 001-01 | E15: 200 | H15: 14 | I15: มิถุนายน 2567 | J15: 45473 | K15: 1 | L15: Sun. สอนตามจริง | N15: U14 | O15: นาย ไชยวัฒน์ ปาลี
A16: =C16&" "&D16 -> 954231 701-01 | B16: นาย เกริก สุริยมณี | C16: 954231 | D16: 701-01 | E16: 300 | H16: 15 | I16: กรกฎาคม 2567 | J16: 45474 | K16: 1 | N16: U15 | O16: นาย จักรพันธ์ ไชยวงค์
A17: =C17&" "&D17 -> 953321 702 | B17: นาย เกริกเกียรติ วงศ์อุทัย | C17: 953321 | D17: 702 | E17: 300 | H17: 16 | I17: กรกฎาคม 2567 | J17: 45475 | K17: 1 | N17: U16 | O17: นาย ชลชาติ อภิศร
A18: =C18&" "&D18 -> 954100 001-1 | B18: นาย เกริกเกียรติ วงศ์อุทัย | C18: 954100 | D18: 001-1 | E18: 200 | H18: 17 | I18: กรกฎาคม 2567 | J18: 45476 | K18: 1 | N18: U17 | O18: นาย ชานน กันยะมี
A19: =C19&" "&D19 -> 954241 701 | B19: นาย เกริกเกียรติ วงศ์อุทัย | C19: 954241 | D19: 701 | E19: 300 | H19: 18 | I19: กรกฎาคม 2567 | J19: 45477 | K19: 1 | N19: U18 | O19: นาย ณัฐพล ศรีโคตร
A20: =C20&" "&D20 -> 954443 001 | B20: นาย เกริกเกียรติ วงศ์อุทัย | C20: 954443 | D20: 001 | E20: 200 | H20: 19 | I20: กรกฎาคม 2567 | J20: 45478 | K20: 1 | N20: U19 | O20: นาย ณัฐภูมิ อินสวรรค์
A21: =C21&" "&D21 -> 958225 001 | B21: นาย เตชณัฐ อัครจาคะ | C21: 958225 | D21: 001 | E21: 200 | H21: 20 | I21: กรกฎาคม 2567 | J21: 45479 | K21: 1 | L21: Sat. สอนตามจริง | N21: U20 | O21: นาย นพพร สินสวัสดิ์
A22: =C22&" "&D22 -> 958481 001 | B22: นาย ไชยวัฒน์ ปาลี | C22: 958481 | D22: 001 | E22: 200 | H22: 21 | I22: กรกฎาคม 2567 | J22: 45480 | K22: 1 | L22: Sun. สอนตามจริง | N22: U21 | O22: นาย พฤฒพงศ์ ชุ่มชื่น
A23: =C23&" "&D23 -> 958321 002 | B23: นาย จักรพันธ์ ไชยวงค์ | C23: 958321 | D23: 002 | E23: 200 | H23: 22 | I23: กรกฎาคม 2567 | J23: 45481 | K23: 1 | N23: U22 | O23: นาย ภูริช ชัยรัตน์
A24: =C24&" "&D24 -> 958341 001 | B24: นาย จักรพันธ์ ไชยวงค์ | C24: 958341 | D24: 001 | E24: 200 | H24: 23 | I24: กรกฎาคม 2567 | J24: 45482 | K24: 1 | N24: U23 | O24: นาย มัฆวาน บุญวงศ์
A25: =C25&" "&D25 -> 960212 001 | B25: นาย ชลชาติ อภิศร | C25: 960212 | D25: 001 | E25: 200 | H25: 24 | I25: กรกฎาคม 2567 | J25: 45483 | K25: 1 | N25: U24 | O25: นาย รัชกัญจน์ คุณชยางกูร
A26: =C26&" "&D26 -> 954100 001-2 | B26: นาย ชานน กันยะมี | C26: 954100 | D26: 001-2 | E26: 200 | H26: 25 | I26: กรกฎาคม 2567 | J26: 45484 | K26: 1 | N26: U25 | O26: นาย รัชพล สรณถาวรกุล
A27: =C27&" "&D27 -> 954140 702 | B27: นาย ชานน กันยะมี | C27: 954140 | D27: 702 | E27: 300 | H27: 26 | I27: กรกฎาคม 2567 | J27: 45485 | K27: 1 | N27: U26 | O27: นาย วณิชย์ นีลดานุวงศ์
A28: =C28&" "&D28 -> 957331 001 | B28: นาย ชานน กันยะมี | C28: 957331 | D28: 001 | E28: 200 | H28: 27 | I28: กรกฎาคม 2567 | J28: 45486 | K28: 1 | L28: Sat. สอนตามจริง | M28: {=IF($D$3=Maintable!$G$2,Maintable!$J$2:$J$19,IF($D$3=Maintable!$G$3,Maintable!$J$20:$J$50,IF($D$3=Maintable!$G$4,Maintable!$J$51:$J$81,IF($D$3=Maintable!$G$5,Maintable!$J$82:$J$110,Maintable!$J$111:$J$118))))} -> 45569 | N28: U27 | O28: นาย วัชรชัย ไชยวุฒิ
A29: =C29&" "&D29 -> 957335 001 | B29: นาย ชานน กันยะมี | C29: 957335 | D29: 001 | E29: 200 | H29: 28 | I29: กรกฎาคม 2567 | J29: 45487 | K29: 1 | L29: Sun. สอนตามจริง | M29: 45570 | N29: U28 | O29: นาย วันพิรุฬ แหกาวี
A30: =C30&" "&D30 -> 958111 002 | B30: นาย ชานน กันยะมี | C30: 958111 | D30: 002 | E30: 200 | H30: 29 | I30: กรกฎาคม 2567 | J30: 45488 | K30: 1 | M30: 45571 | N30: U29 | O30: นาย ศุภกร กันทะวงศ์
A31: =C31&" "&D31 -> 958261 002 | B31: นาย ชานน กันยะมี | C31: 958261 | D31: 002 | E31: 200 | H31: 30 | I31: กรกฎาคม 2567 | J31: 45489 | K31: 1 | M31: 45572 | N31: U30 | O31: นาย สิรวิชญ์ เซี่ยงฉิน
A32: =C32&" "&D32 -> 954449 701 | B32: นาย ณัฐพล ศรีโคตร | C32: 954449 | D32: 701 | E32: 300 | H32: 31 | I32: กรกฎาคม 2567 | J32: 45490 | K32: 1 | M32: 45573 | N32: U31 | O32: นาย หัฐชัย รอดภัย
A33: =C33&" "&D33 -> 958331 002 | B33: นาย ณัฐภูมิ อินสวรรค์ | C33: 958331 | D33: 002 | E33: 200 | H33: 32 | I33: กรกฎาคม 2567 | J33: 45491 | K33: 1 | M33: 45574 | N33: U32
A34: =C34&" "&D34 -> 954100 001-3 | B34: นาย นพพร สินสวัสดิ์ | C34: 954100 | D34: 001-3 | E34: 200 | H34: 33 | I34: กรกฎาคม 2567 | J34: 45492 | K34: 1 | M34: 45575
A35: =C35&" "&D35 -> 955102 702 | B35: นาย นพพร สินสวัสดิ์ | C35: 955102 | D35: 702 | E35: 300 | H35: 34 | I35: กรกฎาคม 2567 | J35: 45493 | K35: 1 | L35: Sat. สอนตามจริง | M35: 45576
A36: =C36&" "&D36 -> 958102 001 | B36: นาย พฤฒพงศ์ ชุ่มชื่น | C36: 958102 | D36: 001 | E36: 200 | H36: 35 | I36: กรกฎาคม 2567 | J36: 45494 | K36: 1 | L36: Sun. สอนตามจริง
A37: =C37&" "&D37 -> 958261 003 | B37: นาย พฤฒพงศ์ ชุ่มชื่น | C37: 958261 | D37: 003 | E37: 200 | H37: 36 | I37: กรกฎาคม 2567 | J37: 45495 | K37: 1 | L37: วันหยุดฯ สอนชดเชย
A38: =C38&" "&D38 -> 954140 002 | B38: นาย ภูริช ชัยรัตน์ | C38: 954140 | D38: 002 | E38: 200 | H38: 37 | I38: กรกฎาคม 2567 | J38: 45496 | K38: 1
A39: =C39&" "&D39 -> 958481 003 | B39: นาย ภูริช ชัยรัตน์ | C39: 958481 | D39: 003 | E39: 200 | H39: 38 | I39: กรกฎาคม 2567 | J39: 45497 | K39: 1
A40: =C40&" "&D40 -> 957213 001 | B40: นาย มัฆวาน บุญวงศ์ | C40: 957213 | D40: 001 | E40: 200 | H40: 39 | I40: กรกฎาคม 2567 | J40: 45498 | K40: 1
...

Sheet Course_list
A1: Key | B1: ชื่อผู้สอน | C1: รหัสวิชา | D1: Section | E1: Rate
A2: =C2&" "&D2 -> 955103 701 | B2: นางสาว Chen Yang | C2: 955103 | D2: 701 | E2: 300
A3: =C3&" "&D3 -> 953201 701 | B3: นางสาว Haitao Liu | C3: 953201 | D3: 701 | E3: 300
A4: =C4&" "&D4 -> 953321 701 | B4: นางสาว Haitao Liu | C4: 953321 | D4: 701 | E4: 300
A5: =C5&" "&D5 -> 951312 001 | B5: นางสาว เพ็ญศิริ นิจประกิจ | C5: 951312 | D5: 001 | E5: 200
A6: =C6&" "&D6 -> 958261 001 | B6: นางสาว เพ็ญศิริ นิจประกิจ | C6: 958261 | D6: 001 | E6: 200
A7: =C7&" "&D7 -> 958481 004 | B7: นางสาว ธนธรณ์ ปัญญาแก้ว | C7: 958481 | D7: 004 | E7: 200
A8: =C8&" "&D8 -> 954347 001 | B8: นางสาว พิมพ์ชนก กลิ่นจันทร์ | C8: 954347 | D8: 001 | E8: 200
A9: =C9&" "&D9 -> 954231 002-01 | B9: นางสาว พิมพิกา สุภาวงค์ | C9: 954231 | D9: 002-01 | E9: 200
A10: =C10&" "&D10 -> 951106 001 | B10: นางสาว ภคมณฑ์ กรสังข์ | C10: 951106 | D10: 001 | E10: 200
A11: =C11&" "&D11 -> 960141 001-1 | B11: นางสาว มนัสนันท์ ขันทอง | C11: 960141 | D11: 001-1 | E11: 200
A12: =C12&" "&D12 -> 960231 001 | B12: นางสาว มนัสนันท์ ขันทอง | C12: 960231 | D12: 001 | E12: 200
A13: =C13&" "&D13 -> 960331 001 | B13: นางสาว วณัทชญา แก้ววงวาน | C13: 960331 | D13: 001 | E13: 200
A14: =C14&" "&D14 -> 953212 703 | B14: นาย Shengzhe Huang | C14: 953212 | D14: 703 | E14: 300
A15: =C15&" "&D15 -> 954231 001-01 | B15: นาย เกริก สุริยมณี | C15: 954231 | D15: 001-01 | E15: 200
A16: =C16&" "&D16 -> 954231 701-01 | B16: นาย เกริก สุริยมณี | C16: 954231 | D16: 701-01 | E16: 300
A17: =C17&" "&D17 -> 953321 702 | B17: นาย เกริกเกียรติ วงศ์อุทัย | C17: 953321 | D17: 702 | E17: 300
A18: =C18&" "&D18 -> 954100 001-1 | B18: นาย เกริกเกียรติ วงศ์อุทัย | C18: 954100 | D18: 001-1 | E18: 200
A19: =C19&" "&D19 -> 954241 701 | B19: นาย เกริกเกียรติ วงศ์อุทัย | C19: 954241 | D19: 701 | E19: 300
A20: =C20&" "&D20 -> 954443 001 | B20: นาย เกริกเกียรติ วงศ์อุทัย | C20: 954443 | D20: 001 | E20: 200
A21: =C21&" "&D21 -> 958225 001 | B21: นาย เตชณัฐ อัครจาคะ | C21: 958225 | D21: 001 | E21: 200
A22: =C22&" "&D22 -> 958481 001 | B22: นาย ไชยวัฒน์ ปาลี | C22: 958481 | D22: 001 | E22: 200
A23: =C23&" "&D23 -> 958321 002 | B23: นาย จักรพันธ์ ไชยวงค์ | C23: 958321 | D23: 002 | E23: 200
A24: =C24&" "&D24 -> 958341 001 | B24: นาย จักรพันธ์ ไชยวงค์ | C24: 958341 | D24: 001 | E24: 200
A25: =C25&" "&D25 -> 960212 001 | B25: นาย ชลชาติ อภิศร | C25: 960212 | D25: 001 | E25: 200
A26: =C26&" "&D26 -> 954100 001-2 | B26: นาย ชานน กันยะมี | C26: 954100 | D26: 001-2 | E26: 200
A27: =C27&" "&D27 -> 954140 702 | B27: นาย ชานน กันยะมี | C27: 954140 | D27: 702 | E27: 300
A28: =C28&" "&D28 -> 957331 001 | B28: นาย ชานน กันยะมี | C28: 957331 | D28: 001 | E28: 200
A29: =C29&" "&D29 -> 957335 001 | B29: นาย ชานน กันยะมี | C29: 957335 | D29: 001 | E29: 200
A30: =C30&" "&D30 -> 958111 002 | B30: นาย ชานน กันยะมี | C30: 958111 | D30: 002 | E30: 200
A31: =C31&" "&D31 -> 958261 002 | B31: นาย ชานน กันยะมี | C31: 958261 | D31: 002 | E31: 200
A32: =C32&" "&D32 -> 954449 701 | B32: นาย ณัฐพล ศรีโคตร | C32: 954449 | D32: 701 | E32: 300
A33: =C33&" "&D33 -> 958331 002 | B33: นาย ณัฐภูมิ อินสวรรค์ | C33: 958331 | D33: 002 | E33: 200
A34: =C34&" "&D34 -> 954100 001-3 | B34: นาย นพพร สินสวัสดิ์ | C34: 954100 | D34: 001-3 | E34: 200
A35: =C35&" "&D35 -> 955102 702 | B35: นาย นพพร สินสวัสดิ์ | C35: 955102 | D35: 702 | E35: 300
A36: =C36&" "&D36 -> 958102 001 | B36: นาย พฤฒพงศ์ ชุ่มชื่น | C36: 958102 | D36: 001 | E36: 200
A37: =C37&" "&D37 -> 958261 003 | B37: นาย พฤฒพงศ์ ชุ่มชื่น | C37: 958261 | D37: 003 | E37: 200
A38: =C38&" "&D38 -> 954140 002 | B38: นาย ภูริช ชัยรัตน์ | C38: 954140 | D38: 002 | E38: 200
A39: =C39&" "&D39 -> 958481 003 | B39: นาย ภูริช ชัยรัตน์ | C39: 958481 | D39: 003 | E39: 200
A40: =C40&" "&D40 -> 957213 001 | B40: นาย มัฆวาน บุญวงศ์ | C40: 957213 | D40: 001 | E40: 200
...

Sheet F-12 ใบเบิกค่าสอน(Eng Version)
A1: Requisition Form of Lecturer
A2: College of Arts Media and Technology
A3: Date………………………………….……………..
A5: ( ) Graduate | D5: ( ) Full Time
A6: ( ) Undergraduate | D6: ( ) Part-Time
D7: ( ) International
A9: Lecturer | B9: Date | C9: Course | D9: Amount of hours | E9: Baht/hr. | F9: Total Amount | G9: Payee
A24: Total Amount………………………..Baht..(………………………..………………………………………)
