Workbook

Sheet รายขื่ออาจารย์
A1: ลำดับ | B1: ชื่อ-สกุล
A2: 1 | B2: กชณิช วรรณโกษฐ
A3: 2 | B3: กรรณิกาณ์ ด้วงเจริญ
A4: 3 | B4: กฤตวยาน์ ทองคู่
A5: 4 | B5: คณิตา ตุมพสุวรรณ
A6: 5 | B6: จิรพัฒน์ วาณิชวัฒนะโกศล
A7: 6 | B7: จิราวิทย์ ญาณจินดา
A8: 7 | B8: ดนัยธัญ พงษ์พัชราธรเทพ
A9: 8 | B9: นภาพร รีวีระกุล
A10: 9 | B10: บุณฑริกา ปภาวสิทธิ์
A11: 10 | B11: พชร ตินะมาส
A12: 11 | B12: พรธิดา แก้วกมล
A13: 12 | B13: ภคินี อริยะ
... A23: 22 | B23: อฬิญญา พงษ์วาท
B25: จิรพิพัฒน์ ธัญพงษ์ภัทร
B26: นัยน์รัตน์ กันยะมี
B27: นพชัย วงค์สาย
B28: สุรักษ์ อุดมสม
B31: พงษ์ตะวัน
B32: เก่ง
B33: วิจิตร
B34: นพพร

Sheet ภาระงานสอน
B1: สอนเดี่ยว | C1: สอนร่วม | D1: สอนนอกหลักสูตร โท-เอก (ระบุวิชา สอนคนเดียวหรืออย่างไร) | E1: รวมภาระงานสอน
A2: กชณิช วรรณโกษฐ | B2: =SUMIF('รายวิชาที่เปิดสอน'!E$3:E$91, A2, 'รายวิชาที่เปิดสอน'!D$3:D$91) -> 5.4 | E2: =SUM(B2:C2)*3 -> 16.2 | F2: =E2*15 -> 243 | G2: +953111 | H2: IE/IT
A3: กรรณิกาณ์ ด้วงเจริญ | B3: =SUMIF('รายวิชาที่เปิดสอน'!E$3:E$91, A3, 'รายวิชาที่เปิดสอน'!D$3:D$91) -> 9 | E3: =SUM(B3:C3)*3 -> 27 | F3: =E3*15 -> 405 | H3: IT
A4: กฤตวยาน์ ทองคู่ | B4: =SUMIF('รายวิชาที่เปิดสอน'!E$3:E$91, A4, 'รายวิชาที่เปิดสอน'!D$3:D$91) -> 6 | E4: =SUM(B4:C4)*3 -> 18 | F4: =E4*15 -> 270 | H4: IT
A5: คณิตา ตุมพสุวรรณ | B5: =SUMIF('รายวิชาที่เปิดสอน'!E$3:E$91, A5, 'รายวิชาที่เปิดสอน'!D$3:D$91) -> 7.5 | E5: =SUM(B5:C5)*3 -> 22.5 | F5: =E5*15 -> 337.5 | H5: MM
A6: จิรพัฒน์ วาณิชวัฒนะโกศล | B6: =SUMIF('รายวิชาที่เปิดสอน'!E$3:E$91, A6, 'รายวิชาที่เปิดสอน'!D$3:D$91) -> 6 | E6: =SUM(B6:C6)*3 -> 18 | F6: =E6*15 -> 270 | H6: IE
A7: จิราวิทย์ ญาณจินดา | B7: =SUMIF('รายวิชาที่เปิดสอน'!E$3:E$91, A7, 'รายวิชาที่เปิดสอน'!D$3:D$91) -> 6 | E7: =SUM(B7:C7)*3 -> 18 | F7: =E7*15 -> 270 | H7: KM
A8: ดนัยธัญ พงษ์พัชราธรเทพ | B8: =SUMIF('รายวิชาที่เปิดสอน'!E$3:E$91, A8, 'รายวิชาที่เปิดสอน'!D$3:D$91) -> 0 | E8: =SUM(B8:C8)*3 -> 0 | F8: =E8*15 -> 0
A9: นภาพร รีวีระกุล | B9: =SUMIF('รายวิชาที่เปิดสอน'!E$3:E$91, A9, 'รายวิชาที่เปิดสอน'!D$3:D$91) -> 6 | E9: =SUM(B9:C9)*3 -> 18 | F9: =E9*15 -> 270 | H9: IE/KM
A10: บุณฑริกา ปภาวสิทธิ์ | B10: =SUMIF('รายวิชาที่เปิดสอน'!E$3:E$91, A10, 'รายวิชาที่เปิดสอน'!D$3:D$91) -> 6 | E10: =SUM(B10:C10)*3 -> 18 | F10: =E10*15 -> 270 | H10: MM
A11: พชร ตินะมาส | B11: =SUMIF('รายวิชาที่เปิดสอน'!E$3:E$91, A11, 'รายวิชาที่เปิดสอน'!D$3:D$91) -> 6 | E11: =SUM(B11:C11)*3 -> 18 | F11: =E11*15 -> 270 | H11: IT
A12: พรธิดา แก้วกมล | B12: =SUMIF('รายวิชาที่เปิดสอน'!E$3:E$91, A12, 'รายวิชาที่เปิดสอน'!D$3:D$91) -> 9 | E12: =SUM(B12:C12)*3 -> 27 | F12: =E12*15 -> 405 | H12: IT
A13: ภคินี อริยะ | B13: =SUMIF('รายวิชาที่เปิดสอน'!E$3:E$91, A13, 'รายวิชาที่เปิดสอน'!D$3:D$91) -> 9 | E13: =SUM(B13:C13)*3 -> 27 | F13: =E13*15 -> 405 | H13: MM
A14: ภัทรพร คูวุฒยากร | B14: =SUMIF('รายวิชาที่เปิดสอน'!E$3:E$91, A14, 'รายวิชาที่เปิดสอน'!D$3:D$91) -> 6 | E14: =SUM(B14:C14)*3 -> 18 | F14: =E14*15 -> 270 | H14: IE/IT/MM
A15: ภาสิทธิ์ เจริญขวัญ | B15: =SUMIF('รายวิชาที่เปิดสอน'!E$3:E$91, A15, 'รายวิชาที่เปิดสอน'!D$3:D$91) -> 6 | E15: =SUM(B15:C15)*3 -> 18 | F15: =E15*15 -> 270 | H15: IT
A16: รัฐพล วุฒิการณ์ | B16: =SUMIF('รายวิชาที่เปิดสอน'!E$3:E$91, A16, 'รายวิชาที่เปิดสอน'!D$3:D$91) -> 6 | E16: =SUM(B16:C16)*3 -> 18 | F16: =E16*15 -> 270 | H16: KM/IE
A17: รัศมิ์ลภัส สุตีคา | B17: =SUMIF('รายวิชาที่เปิดสอน'!E$3:E$91, A17, 'รายวิชาที่เปิดสอน'!D$3:D$91) -> 6.9 | E17: =SUM(B17:C17)*3 -> 20.7 | F17: =E17*15 -> 310.5 | H17: IT
A18: วรธมณ จีระผานุกร | B18: =SUMIF('รายวิชาที่เปิดสอน'!E$3:E$91, A18, 'รายวิชาที่เปิดสอน'!D$3:D$91) -> 7.5 | E18: =SUM(B18:C18)*3 -> 22.5 | F18: =E18*15 -> 337.5 | H18: MM
A19: วรวิชญ์ จันทร์ฉาย | B19: =SUMIF('รายวิชาที่เปิดสอน'!E$3:E$91, A19, 'รายวิชาที่เปิดสอน'!D$3:D$91) -> 3 | E19: =SUM(B19:C19)*3 -> 9 | F19: =E19*15 -> 135 | H19: IE/KM
A20: สมเกียรติ น่วมนา | B20: =SUMIF('รายวิชาที่เปิดสอน'!E$3:E$91, A20, 'รายวิชาที่เปิดสอน'!D$3:D$91) -> 6 | E20: =SUM(B20:C20)*3 -> 18 | F20: =E20*15 -> 270 | H20: IE/IT
A21: สิริกร สันติโรจนกุล | B21: =SUMIF('รายวิชาที่เปิดสอน'!E$3:E$91, A21, 'รายวิชาที่เปิดสอน'!D$3:D$91) -> 9 | E21: =SUM(B21:C21)*3 -> 27 | F21: =E21*15 -> 405 | H21: IT
A22: อรวิชย์ ถิ่นนุกูล | B22: =SUMIF('รายวิชาที่เปิดสอน'!E$3:E$91, A22, 'รายวิชาที่เปิดสอน'!D$3:D$91) -> 8.4 | E22: =SUM(B22:C22)*3 -> 25.2 | F22: =E22*15 -> 378 | G22: 27+ประสานงาน | H22: IT
A23: อฬิญญา พงษ์วาท | B23: =SUMIF('รายวิชาที่เปิดสอน'!E$3:E$91, A23, 'รายวิชาที่เปิดสอน'!D$3:D$91) -> 6 | E23: =SUM(B23:C23)*3 -> 18 | F23: =E23*15 -> 270 | H23: MM/IT
A25: อาจารย์นอกหลักสูตร
A26: จิรพิพัฒน์ ธัญพงษ์ภัทร | B26: =SUMIF('รายวิชาที่เปิดสอน'!E$3:E$91, A26, 'รายวิชาที่เปิดสอน'!D$3:D$91) -> 3 | E26: =SUM(B26:C26)*3 -> 9
A27: นัยน์รัตน์ กันยะมี | B27: =SUMIF('รายวิชาที่เปิดสอน'!E$3:E$91, A27, 'รายวิชาที่เปิดสอน'!D$3:D$91) -> 3 | E27: =SUM(B27:C27)*3 -> 9
A28: นพชัย วงค์สาย | B28: =SUMIF('รายวิชาที่เปิดสอน'!E$3:E$91, A28, 'รายวิชาที่เปิดสอน'!D$3:D$91) -> 3 | E28: =SUM(B28:C28)*3 -> 9
B29: =SUMIF('รายวิชาที่เปิดสอน'!E$3:E$91, A29, 'รายวิชาที่เปิดสอน'!D$3:D$91) -> 0
B30: =SUMIF('รายวิชาที่เปิดสอน'!E$3:E$91, A30, 'รายวิชาที่เปิดสอน'!D$3:D$91) -> 0
A32: อาจารย์พิเศษ
A33: พงษ์ตะวัน | B33: =SUMIF('รายวิชาที่เปิดสอน'!E$3:E$91, A33, 'รายวิชาที่เปิดสอน'!D$3:D$91) -> 0 | E33: =SUM(B33:C33)*3 -> 0
A34: เก่ง | B34: =SUMIF('รายวิชาที่เปิดสอน'!E$3:E$91, A34, 'รายวิชาที่เปิดสอน'!D$3:D$91) -> 0 | E34: =SUM(B34:C34)*3 -> 0
A35: วิจิตร | B35: =SUMIF('รายวิชาที่เปิดสอน'!E$3:E$91, A35, 'รายวิชาที่เปิดสอน'!D$3:D$91) -> 0 | E35: =SUM(B35:C35)*3 -> 0
A36: นพพร | B36: =SUMIF('รายวิชาที่เปิดสอน'!E$3:E$91, A36, 'รายวิชาที่เปิดสอน'!D$3:D$91) -> 0 | E36: =SUM(B36:C36)*3 -> 0
E37: =SUM(B37:C37)*3 -> 0

Sheet รายวิชาที่เปิดสอน
B1: วิชา | C1: ตอนเรียน | D1: หน่วยกิต | E1: ผู้สอน | G1: Note | H1: midterm | J1: Final | K1: Room.
H2: 24 - 30 Aug 2026
A3: 1-69 | B3: 954100 | C3: 001 | D3: 1.5 | E3: คณิตา ตุมพสุวรรณ | H3: 46259
A4: หลักสูตร 65 | D4: 1.5 | E4: อรวิชย์ ถิ่นนุกูล | H4: 12:00-15:00
C5: 002 | D5: 1.5 | E5: อรวิชย์ ถิ่นนุกูล | M5: ตารางสอบ | O5: Final Exam
D6: 1.5 | E6: คณิตา ตุมพสุวรรณ
C7: 701 | D7: 1.5 | E7: คณิตา ตุมพสุวรรณ | M7: PATTERN :
D8: 1.5 | E8: อรวิชย์ ถิ่นนุกูล
C9: 702 | D9: 3 | F9: เปิดสำหรับ econ เรียนร่วม mmit-inter
B11: 954140 | C11: 001 | D11: 3 | E11: พรธิดา แก้วกมล | H11: 46260
C12: 002 | D12: 3 | E12: อฬิญญา พงษ์วาท | H12: 08:00-11:00
C13: 003 | D13: 3 | E13: รัศมิ์ลภัส สุตีคา
C14: 004 | D14: 3 | E14: กชณิช วรรณโกษฐ
C15: 701 | D15: 3 | E15: นพชัย วงค์สาย
B18: 954142 | C18: 001 | D18: 3 | E18: พรธิดา แก้วกมล | H18: 46261 | J18: ขอ 20-22/10
C19: 002 | D19: 3 | E19: กฤตวยาน์ ทองคู่ | H19: 12:00-15:00
C20: 003 | D20: 3 | E20: กรรณิกาณ์ ด้วงเจริญ
C21: 004 | D21: 3 | E21: พรธิดา แก้วกมล
C22: 701 | D22: 3 | E22: กรรณิกาณ์ ด้วงเจริญ
A25: 2-68 | B25: 954230 | C25: 001 | D25: 3 | E25: ภคินี อริยะ | H25: 46259
A26: หลักสูตร 65 | C26: 002 | D26: 3 | E26: วรธมณ จีระผานุกร | H26: 15:30-18:30
C27: 701 | D27: 3 | E27: ภคินี อริยะ
B29: 954231 | C29: 001 | D29: 3 | E29: บุณฑริกา ปภาวสิทธิ์ | H29: 46260
C30: 002 | D30: 3 | E30: วรธมณ จีระผานุกร | H30: 12:00-15:00
C31: 701 | D31: 3 | E31: บุณฑริกา ปภาวสิทธิ์
B33: 954241 | C33: 701 | D33: 3 | E33: นัยน์รัตน์ กันยะมี | H33: 46262
H34: 08:00-11:00
B36: 954244 | C36: 001 | D36: 3 | E36: กฤตวยาน์ ทองคู่ | H36: 46261
C37: 002 | D37: 3 | E37: กรรณิกาณ์ ด้วงเจริญ | H37: 15:30-18:30
C38: 003 | D38: 3 | E38: สมเกียรติ น่วมนา
C39: 701 | D39: 3
B41: 954340 | C41: 001 | D41: 3 | E41: ภาสิทธิ์ เจริญขวัญ | H41: 46258
C42: 002 | D42: 3 | E42: จิรพิพัฒน์ ธัญพงษ์ภัทร | H42: 12:00-15:00
C43: 003 | D43: 3 | E43: สิริกร สันติโรจนกุล
C44: 004 | D44: 3 | E44: พชร ตินะมาส
C45: 701 | D45: 3 | E45: ภาสิทธิ์ เจริญขวัญ
C46: 702 | D46: 3 | E46: สิริกร สันติโรจนกุล
A48: 3-67 | B48: 954310 | C48: 001 | D48: 1.5 | E48: จิรพัฒน์ วาณิชวัฒนะโกศล | H48: 46260
A49: หลักสูตร 65 | D49: 1.5 | E49: ภคินี อริยะ | H49: 15:30-18:30
C50: 002 | D50: 1.5 | E50: กชณิช วรรณโกษฐ
...

Sheet Year 1- 69 (ไทย=130 Inter=40)
A1: ชั้นปีที่ 1 หลักสูตรปรับปรุง พ.ศ.2565 MMIT Year 1 Semester 1/2025 (Curriculum 2022)
B3: 08.00 | D3: 09.00 | F3: 10.00 | H3: 11.00 | J3: 12.00 | L3: 13.00 | N3: 14.00 | P3: 15.00 | R3: 16.00 | T3: 17.00 | V3: จำนวน Seat (Lab)
A4: Monday | B4: 954140 / 001 / 25/ อ.พรธิดา | F4: 954140 / 001 / 25 / C207 | L4: 140104/ Sec.000 | O4: 001101 Sec.00X | V4: C307 | W4: 40 | Y4: *** note
B5: 954140 / 002 / 25 / อ.อฬิญญา | F5: 954140 / 002/ 30 / C302 | V5: C308 | W5: 34 | Y5: รหัส 61/60/59 ใช้หลักสูตร 57
V6: C309 | W6: 36 | Y6: รหัส 62 ใช้หลักสูตร 62
V7: C202 | W7: 36 | Y7: รหัส 63/64 ใช้หลักสูตร 62 GE Transformation
A8: Tuesday | E8: 954100 sec.001 อ.อรวิชย์ (IT) | H8: 954100 sec.002 อ.คณิตา (MM) | L8: 954142 / 001/ 25 / อ.พรธิดา | P8: 954142 / 001 / 25 | T8: C305 | V8: C203 | W8: 36 | Y8: รหัส 65/66 ใช้หลักสูตร 65
E9: 65 คน/CAMT113 | H9: 65 คน/CAMT113 | L9: 954142 / 002 / 25 / อ.กฤตวยาน์ | P9: 954142 / 002 / 25 / C307 | T9: C307 | V9: C204 + 206 | W9: 60
E10: 953111/701 | L10: 954142 / 701 / 20 / อ.กรรณิกาณ์ | P10: 954142 / 701 / 20 /C304 | T10: หาก inter รับ >=40 คน ขอแตก 2 sec | V10: C207 | W10: 40
L11: 954142 / 702 / 20 / อ.พิเศษ | P11: 954142 / 702 / 20 /C203 | V11: C208 | W11: 36
V12: C209 | W12: 36
A13: Wednesday
A15: Thursday | B15: 954140 / 003 / 25 / อ.รัศมิ์ลภัส | F15: 954140 / 003/ 25 / C307 | L15: 140104/ Sec.000 | O15: 001101 Sec.00X
B16: 954140 / 004 / 25 / อ.กชณิช | F16: 954140 / 004 / 25 /C308
B17: 954140 / 701 / 20 / อ.นพชัย | F17: 954140 / 701/ 20 / C207
B18: 954140 / 702 / 20 / อ.นพชัย | F18: 954140 / 702/ 20 / C205 | J18: หาก inter รับ >=40 คน ขอแตก 2 sec
A20: Friday | E20: 954100 sec.001 อ.อรวิชย์ (IT) | H20: 954100 sec.002 อ.คณิตา (MM) | L20: 954142 / 003 / 25 / อ.กรรณิกาณ์ | P20: 954142 / 001 / 25 | T20: C207
E21: 50 คน/CAMT113 | H21: 50 คน/CAMT113 | L21: 954142 / 004 / 25 / อ.พรธิดา | P21: 954142 / 004 / 25 / C305
E22: 953111/701
L23: 954100 sec.701 /40+10 อ.อรวิชย์/ อ.คณิตา (IT+MM) | R23: เปิด 954100 sec702 ให้ econ-inter 10 seats เรียนควบ inter
L24: B303 -- MMIT(40) + Econ (10)
B27: course | C27: name | I27: sec | J27: credit | N27: course | O27: name | T27: sec | U27: credit
B28: 001101 | C28: ภาษาอังกฤษพื้นฐาน 1 | I28: xxx | J28: 3 | K28: ยังไม่ CF | N28: 001101 | O28: Fundamental English 1 | T28: 000 | U28: 3 | V28: ยังไม่ CF
B29: 140104 | C29: การเป็นพลเมือง | I29: xxx | J29: 3 | K29: ยังไม่ CF | N29: 140104 | O29: Citizenship | T29: 000 | U29: 3 | V29: ยังไม่ CF
B30: 954140 | C30: พื้นฐานเทคโนโลยีสารสนเทศ | I30: 001-004 | J30: 3 | K30: ยังไม่ CF | N30: 954140 | O30: Information Technology Literacy | T30: 701 | U30: 3
B31: 954142 | C31: การเขียนโปรแกรมคอมพิวเตอร์พื้นฐาน | I31: 001-004 | J31: 3 | N31: 954142 | O31: Fundamental Computer Prog for MM | T31: 701 | U31: 3
B32: 954100 | C32: ระบบสารสนเทศเพื่อการบริหารและจัดการองค์กร | I32: 001-002 | J32: 3 | N32: 954100 | O32: Information Ssytem for OM | T32: 701 | U32: 3
B33: .............. | C33: วิชาศึกษาทั่วไปเลือก (GE Elective Course) | I33: xxx | J33: 3 | K33: ยังไม่ CF | N33: 953111 | O33: วิชาศึกษาทั่วไปเลือก (GE Elective Course) | T33: 701 | U33: 3 | V33: ยังไม่ CF
S34: Date/Time : TBA
G35: รวมจำนวนหน่วยกิต | J35: =SUM(J28:J34) -> 18 | S35: Total Unit | U35: =SUM(U28:U33) -> 18
B37: อ.โหน่ง DII ขอสอน 140 เพื่อขอตำแหน่งวิชการ

Sheet Year 2-68 (ไทย=98 Inter=46) 
A1: ช้นปีที่ 2 หลักสูตรปรับปรุง พ.ศ.2565 MMIT Year 2 Semester 1/2025 (Curriculum 2022)
B3: 08.00 | D3: 09.00 | F3: 10.00 | H3: 11.00 | J3: 12.00 | L3: 13.00 | N3: 14.00 | P3: 15.00 | R3: 16.00 | T3: 17.00
A4: Monday | E4: 954230 / 701 / อ.ภคินี | H4: 954231 / 701 /อ.บุณฑริกา | L4: 001229 Sec.701
E5: 50 คน / B302 | H5: 50 คน / B302 | L5: นศ.inter
E6: 954231 / 001 /อ.บุณฑริกา | H6: 954230 / 001 / อ.ภคินี
E7: 50 คน / B303 | H7: 50 คน / B303
E8: 954231 / 002 /อ.วรธมณ | H8: 954230 / 002 / อ.วรธมณ | L8: 954340 / 003 / 25 / อ.สิริกร | P8: 954340 / 003 / 25 / C207
E9: 50 คน / CAMT 113 | H9: 50 คน /CAMT 113 | L9: 954340 / 004 / 25 / อ.พชร | P9: 954340 / 004 / 25 / C205
A12: Tuesday | E12: 208262/001 | L12: 208262/002 | O12: 954241/701/50/ B302/อ.นัยน์รัตน์ | S12: เปิดสำหรับ Inter รหัส <=68
E13: นศ.ไทย | L13: นศ.ไทย
B14: 954340 / 701 / 25/ อ.ภาสิทธิ์ | F14: 954340 / 701 / 25/ C201 | L14: 954340 / 001 / 25 / อ.ภาสิทธิ์ | P14: 954340 / 001 / 25 /C307
B15: 954340 / 702 / 25/ อ.สิริกร | F15: 954340 / 702 / 25/ C202 | L15: 954340 / 002 / 25 / อ.จิรพิพัฒน์ | P15: 954340 / 002 / 25 /C309
L16: 888102/705
A17: Wednesday
A20: Thursday | E20: 954230 / 701 / อ.ภคินี | H20: 954231 / 701 /อ.บุณฑริกา | L20: 001229 Sec.701 | O20: 954244 / 001 / 35 / อ.กฤตวยาน์ / B206
E21: 50 คน / B302 | H21: 50 คน / B302 | L21: นศ.inter | O21: 954244 / 002 / 35 / อ.กรรณิกาณ์ / B207
E22: 954231 / 001 /อ.บุณฑริกา | H22: 954230 / 001 / อ.ภคินี | O22: 954244 / 003 / 35 / อ.สมเกียรติ / B208
E23: 50 คน / B303 | H23: 50 คน / B303 | O23: 954244 / 701 / 48 / อ.อ๊อฟ / B303 (อ. คนใหม่)
E24: 954231 / 002 /อ.วรธมณ | H24: 954230 / 002 / อ.วรธมณ
E25: 50 คน / CAMT 113 | H25: 50 คน /CAMT 113
A26: Friday | E26: 954241/701/50/ C204 /อ.นัยน์รัตน์ | L26: 208262/002
E27: 208262/001 | L27: นศ.ไทย
E28: นศ.ไทย
L29: 888102/705
B32: course | D32: name | I32: sec | J32: credit | M32: course | N32: name | T32: sec | U32: credit
A33: สลับจากเทอม 2 | B33: 001229 | D33: ภาษาอังกฤษสำหรับศิลปะ สื่อ | I33: เลือกลงตาม sec ว่างได้เลย | J33: 3 | M33: 001229 | N33: English for Media Arts | T33: 701 | U33: 3
A34: ลงได้ทั้ง 001 และ 002 | B34: 208262 | D34: สถิติเบื้องต้นสำหรับวิทยาศาสตร์และเทคโนโลยี | I34: 001/002 | J34: 3 | M34: 954241 | N34: Introduction to Computational Thinking and Programming | T34: 701 | U34: 3 | V34: CF อ จอยแล้ว
B35: 954230 | D35: การติดตามทางการเงินในธุรกิจดิจิทัล | I35: 001-002 | J35: 3 | M35: 954230 | N35: FI TRACKING IN DIG BUS | T35: 701 | U35: 3
B36: 954231 | D36: ระบบงานการจัดการทุนมนุษย์ในธุรกิจดิจิทัล | I36: 001-002 | J36: 3 | M36: 954231 | N36: Human Capital Management in Digital Business | T36: 701 | U36: 3
B37: 954244 | D37: การอ่อกแบบและวิเคราะห์ระบบ | I37: 001-003 | J37: 3 | M37: 954244 | N37: SYS ANALYSIS & DESIGN FOR MM | T37: 701 | U37: 3
B38: 954340 | D38: การออกแบบฐานข้อมูลองค์กรและการประยุกต์ | I38: 001-004 | J38: 3 | M38: 954340 | N38: Enterprise Database Design and Applications | T38: 701 | U38: 3
D39: วิชาศึกษาทั่วไป (กลุ่มผู้ร่วมสร้างสรรค์นวัตกรรม) | I39: xxx | J39: 3 | M39: 888102 | N39: GE course | T39: 705 | U39: 3
G41: รวมจำนวนหน่วยกิต | J41: =SUM(J33:J39) -> 21 | S41: Total Unit | U41: =SUM(U33:U40) -> 21
A43: ลิ้งสำหรับเช็ค | B43: https://mmit.camt.cmu.ac.th/detail/28 | F43: Link to check the GE course.
A44: กลุ่มวิชา GE
B45: Study plan
B46: 001201 | D46: การอ่านเชิงวิเคราะห์และการเขียนอย่างมีประสิทธิผล
B47: 208262 | D47: สถิติเบื้องต้นสำหรับวิทยาศาสตร์และเทคโนโลยี
B48: 954241 | D48: (For International students)
B49: 954230 | D49: การติดตามทางการเงินในธุรกิจดิจิทัล
...

Sheet  Year 3-67 (ไทย=70 Inter=31)
A1: ปี 3 MMIT ภาคปกติ ภาคการศึกษา 1/68 (หลักสูตรปรับปรุง พ.ศ.2565) MMIT Year 3 Semester 1/2025 (Curriculum 2022)
B3: 08.00 | D3: 09.00 | F3: 10.00 | H3: 11.00 | J3: 12.00 | L3: 13.00 | N3: 14.00 | P3: 15.00 | R3: 16.00 | T3: 17.00 | V3: 18.00
A4: Monday | E4: 954410/001 /25 คน / อ.จิรพัฒน์ / B206 | L4: 954310 / 001 / อ.จิรพัฒน์ | O4: 954310 / 701 / อ.จิรพัฒน์
E5: 954423 / 001 / 25 / อ.คณิตา / B201 | L5: 35 คน/B201 | O5: 35 คน/ B201
L6: 954310 / 002 / อ. กชณิช | O6: 954365 / 001 / อ.จิราวิทย์
L7: 35 คน/ B202 | O7: 35 คน/B202
L8: 954365 / 701 / อ. จิราวิทย์ | O8: 954365 / 002 / อ.วรวิชญ์
L9: 35 คน/ B203 | O9: 35 คน/B205
A12: Tuesday | B12: 159151/701 (Inter)/SB 4107 | E12: 954477/ 001 / 25 / อ.สมเกียรติ/B202 | L12: 954443 / 001 / 25 / อ.รัศมิ์ลภัส | P12: 954443 / 001 / 25 /C207
E13: 954425/001 /25 คน / อ.อฬิญญา /B206 | L13: 954417 / 701 / 35/ อ.ภัทรพร /C208
L14: 954417 / 001 / 19/ อ.ภัทรพร /C208
A15: Wednesday | B15: 954381 / 001,701 / คณาจารย์ / B304 | L15: 253372 / 701 / 25 / อ.อรวิชย์ /B202
L16: 954491 / 701 / 25 / อ.อรวิชย์ /B201
A17: Thursday | E17: 954413/001 /25 / อ.รัฐพล/B202 | L17: 954310 / 001 / อ.จิรพัฒน์ | O17: 954310 / 701 / อ.จิรพัฒน์
E18: 954430/ 701 / 30/ อ.นภาพร / B206 | L18: 35 คน/B201 | O18: 35 คน/ B201
L19: 954310 / 002 / อ. กชณิช | O19: 954365 / 001 / อ.จิราวิทย์
B20: 954450/001 /อ.อรวิชย์ / 25 คน / C304 | L20: 35 คน/ B202 | O20: 35 คน/B202
L21: 954365 / 701 / อ. จิราวิทย์ | O21: 954365 / 002 / อ.วรวิชญ์
L22: 35 คน/ B203 | O22: 35 คน/B205
A25: Friday | B25: 159151/701 (Inter)/SB 4107 | E25: 954413/701 / 30 / อ.รัฐพล/ B202 | L25: 954348 / 001 / 25 / อ.พชร | P25: 954348 / 001 / 25 /C201
E26: 954430/ 001 / 25 / อ.นภาพร /B203 | L26: 954347 / 001 / 25 / อ.สิริกร B201 | P26: 954347 / 001 / 25 /C202
E27: 954491 / 001/ / 25 / อ.ภัทรพร /B206
E28: 253371 / 001 / 25 /B209
B31: course | C31: name | I31: sec | J31: credit | N31: course | O31: name | U31: sec | V31: credit
B32: 954310 | C32: ระบบสารสนเทศเพื่อการวางแผนทรัพยากรองค์กร | I32: 001-003 | J32: 3 | N32: 954310 | O32: Info System for Enterprise Resource Planning | U32: 701 | V32: 3
B33: 954365 | C33: ระบบการจัดการความรู้ | I33: 001-003 | J33: 3 | N33: 954365 | O33: Knowledge Management System | U33: 701 | V33: 3
B34: 954381 | C34: การเตรียมความพร้อมสำหรับการเรียนรู้ร่วมกับการทำงาน | I34: 001 | J34: 3 | N34: 954381 | O34: Pre for Work Integrated Learning | U34: 701 | V34: 3
C35: วิชาเอกเลือก | I35: xxx | J35: 3 | O35: MAJOR ELECTIVE | U35: xxx | V35: 3
C36: วิชาเอกเลือก | I36: xxx | J36: 3 | O36: MAJOR ELECTIVE | U36: xxx | V36: 3
C37: วิชาเอกเลือก | I37: xxx | J37: 3 | O37: MAJOR ELECTIVE | U37: xxx | V37: 3
D39: รวมจำนวนหน่วยกิต | J39: =SUM(J32:J37) -> 18 | P39: Total Credit | V39: =SUM(V32:V38) -> 18
D41: ลิ้งสำหรับเช็ค | E41: https://mmit.camt.cmu.ac.th/detail/28 | I41: Link to check the GE course.
D42: กลุ่มวิชา GE
A45: List of Major Electives (3rd - 4th Year) | N45: Major Electives Number of Seats (3rd - 4th Year)
A46: No | B46: Type | C46: Course | D46: Name | G46: sec | H46: Seat | I46: Lecturer | J46: Remark | N46: 3rd Year | P46: COOP | Q46: Total | S46: 4th Year | U46: IS | V46: COOP | W46: Total
A47: 1 | B47: IT | C47: 954347 | D47: E-Com | G47: 001 | H47: 25 | I47: สิริกร สันติโรจนกุล | J47: Lab | N47: Estimate Seat | Q47: =P48+P49 -> 105 | S47: Estimate Seat
A48: 2 | B48: IT | C48: 954348 | D48: Web | G48: 001 | H48: 25 | I48: พชร ตินะมาส | J48: Lab | O48: Thai | P48: 70 | U48: =107-V48 -> 16 | V48: 91
A49: 3 | B49: MM | C49: 954423 | D49: Inno | G49: 001 | H49: 25 | I49: คณิตา ตุมพสุวรรณ | J49: Lect | O49: Inter | P49: 35 | U49: =19-V49 -> 11 | V49: 8
A50: 4 | B50: MM | C50: 954425 | D50: Digi Mk | G50: 001 | H50: 25 | I50: อฬิญญา พงษ์วาท | J50: Lect | N50: Need (subjects) | Q50: 3 | S50: Need | U50: 1
A51: 5 | B51: IE | C51: 954477 | D51: IT PP | G51: 001 | H51: 25 | I51: สมเกียรติ น่วมนา | J51: Lect | N51: Total Seats | Q51: =sum(P52:P53) -> 315 | S51: Total Seats | U51: =SUM(U48:U49) -> 27
...

Sheet ปี 4 -66 (ไทย=107 Inter=19) 
A1: ปี 4 MMIT ภาคปกติ ภาคการศึกษา 1/65 (หลักสูตรปรับปรุง พ.ศ.2562:Ge Transformation) MMIT Year 4 Semester 1/2023 (Curriculum 2019 & Ge Transformation)
B3: 08.00 | D3: 09.00 | F3: 10.00 | H3: 11.00 | J3: 12.00 | L3: 13.00 | N3: 14.00 | P3: 15.00 | R3: 16.00 | T3: 17.00
A4: Monday
A8: Tuesday
A12: Wednesday
A14: Thursday
A18: Friday
B23: course | C23: name | I23: sec | J23: credit | M23: course | N23: name | T23: sec | U23: credit
A24: COOP | B24: 954484 | C24: การเรียนรู้ร่วมการทำงาน 1 | J24: 6 | M24: 954484 | N24: Work Integrated Learning 1 | U24: 6
D25: รวมจำนวนหน่วยกิต | J25: 6 | O25: รวมจำนวนหน่วยกิต | U25: 6
A28: IS | B28: 954489 | C28: การฝึกงาน | J28: 3 | M28: 954489 | N28: Job Training | U28: 3
B29: ............ | C29: วิชาเอกเลือก | J29: 3 | M29: ............ | N29: Major Elective | U29: 3
D30: รวมจำนวนหน่วยกิต | J30: 6 | O30: รวมจำนวนหน่วยกิต | U30: 6
