Workbook

Sheet ปี1 (รหัส68) เทอม1-68 (56)
A1: ตารางเรียนสาขาวิชาดิจิทัลเกม สำหรับนักศึกษาชั้นปีที่ 1 (รหัส68)
A2: ภาคการศึกษาที่ 1 ปีการศึกษา 2568
I3: (จำนวนนักศึกษา 56 คน)
B4: 08.00 | D4: 09.00 | F4: 10.00 | H4: 11.00 | J4: 12.00 | L4: 13.00 | N4: 14.00 | P4: 15.00 | R4: 16.00 | T4: 17.00 | V4: 18.00
A5: Monday | E5: 013110 Psychology and Daily Life | H5: 001101 Fundamental English 1 | L5: 958111/001 COMP & PROGRAM FOR GAME 1 25 คน (และมีเด็กตกค้างรวมประมาณ 30 คน) ผศ.ดร.กฤติยา ห้อง ILC B304-306 ย้ายไปเรียนวันพุธ เนื่องจาก ห้องมีไม่เพียงพอ | N5: 958111/001 COMP & PROGRAM FOR GAME 1 ผศ.ดร.กฤติยา 001 (จองห้อง LAB C204+C206) ย้ายไปเรียนวันพุธ เนื่องจาก ห้องมีไม่เพียงพอ
L7: 958111/002 COMP & PROGRAM FOR GAME 1 30 คน อ.นพพล คณาจารย์ เปลี่ยนเป็น ผศ.ดร.ธีรวัฒน์ ILC B304-306 ย้ายไปเรียนวันพุธ เนื่องจาก ห้องมีไม่เพียงพอ | N7: 958111/002 COMP & PROGRAM FOR GAME 1 อ.นพพล คณาจารย์ เปลี่ยนเป็น ผศ.ดร.ธีรวัฒน์ 001 (จองห้อง LAB C204+C206) ย้ายไปเรียนวันพุธ เนื่องจาก ห้องมีไม่เพียงพอ
A9: tuesday | E9: 801100 Architecture in Everyday Life | H9: 140104 Citizenship | L9: 958102/001 Introduction to Digital Games 60 คน อ.ดร. ศุภรา เปลี่ยนเป็น ผศ.ดร.ธีรวัฒน์ ILC B304+B306
A11: wednesday | L11: 958111/001 COMP & PROGRAM FOR GAME 1 25 คน (และมีเด็กตกค้างรวมประมาณ 30 คน) ผศ.ดร.กฤติยา ห้อง ILC B304-306 | N11: 958111/001 COMP & PROGRAM FOR GAME 1 ผศ.ดร.กฤติยา 001 (จองห้อง LAB C204+C206)
L13: 958111/002 COMP & PROGRAM FOR GAME 1 30 คน อ.นพพล คณาจารย์ เปลี่ยนเป็น ผศ.ดร.ธีรวัฒน์ ILC B304-306 | N13: 958111/002 COMP & PROGRAM FOR GAME 1 อ.นพพล คณาจารย์ เปลี่ยนเป็น ผศ.ดร.ธีรวัฒน์ (จองห้อง LAB C204+C206)
A15: thursday | E15: 013110 Psychology and Daily Life | H15: 001101 Fundamental English 1
A17: Friday | E17: 801100 Architecture in Everyday Life | H17: 140104 Citizenship | L17: 958102/001 Introduction to Digital Games 60 คน อ.ดร. ศุภรา เปลี่ยนเป็น อ.เอ๋ ILC B304 + 306 ไม่สามารถสอน อังคาร/ศุกร์ ได้ เนื่องจาก เวลาชนกับการสอนวิชาปี 3 ของ อ.เอ๋ 958441 ดังนั้น จึงเรียนวันอังคารยาว 3 ชม. (17 มิย.68)
Y19: ถาม อ.เอม อีกที
A20: Saturday
A21: Sunday
Q24: วิทยากร | T24: อาจารย์พิเศษ | V24: TA | X24: ชื่ออาจารย์ | Y24: เวลา ชม./สัปดาห์ | Z24: จำนวนสัปดาห์ | AA24: สรุปค่าตอบแทน
A25: สถานนะตรวจสอบ | B25: ลำดับ | C25: รหัสวิชา | D25: รายวิชา | K25: หน่วยกิต | L25: อ.ผู้สอน | M25: ห้องเรียน | N25: หมายเหตุ | Q25: Lec (600) | R25: Lec (1000) | S25: Lec (1500) | T25: Lec (600) | U25: Lab (450) | V25: Lec (200) | W25: Lab (200)
A26: ยังไม่ได้ตรวจสอบ | B26: 1 | C26: 958102 | D26: Introduction to Digital Games | K26: =VLOOKUP($C26,'DG2562V1.2Courses'!$B$4:$F$99,4,FALSE) -> 3 | L26: อ.ดร.ศุภรา | M26: 113,c307,c208 | V26: 4
A27: ยังไม่ได้ตรวจสอบ | B27: 2 | C27: 958111 | D27: =VLOOKUP($C27,'DG2562V1.2Courses'!$B$4:$F$99,3,FALSE) -> Computer and Programming for Game 1 | K27: =VLOOKUP($C27,'DG2562V1.2Courses'!$B$4:$F$99,4,FALSE) -> 3 | L27: ผศ.ดร.กฤติยา | M27: 113,c204,c206,C208 | V27: 4
A28: ยังไม่ได้ตรวจสอบ | B28: 3 | C28: 013110 | D28: =VLOOKUP($C28,'DG2562V1.2Courses'!$B$4:$F$99,3,FALSE) -> Psychology and Daily Life | K28: =VLOOKUP($C28,'DG2562V1.2Courses'!$B$4:$F$99,4,FALSE) -> 3
A29: ยังไม่ได้ตรวจสอบ | B29: 4 | C29: 140104 | D29: =VLOOKUP($C29,'DG2562V1.2Courses'!$B$4:$F$99,3,FALSE) -> Citizenship | K29: =VLOOKUP($C29,'DG2562V1.2Courses'!$B$4:$F$99,4,FALSE) -> 3
A30: ยังไม่ได้ตรวจสอบ | B30: 5 | C30: 801100 | D30: =VLOOKUP($C30,'DG2562V1.2Courses'!$B$4:$F$99,3,FALSE) -> Architecture in Everyday Life | K30: =VLOOKUP($C30,'DG2562V1.2Courses'!$B$4:$F$99,4,FALSE) -> 3
A31: ยังไม่ได้ตรวจสอบ | B31: 6 | C31: 001101 | D31: =VLOOKUP($C31,'DG2562V1.2Courses'!$B$4:$F$99,3,FALSE) -> Fundamental English 1 | K31: =VLOOKUP($C31,'DG2562V1.2Courses'!$B$4:$F$99,4,FALSE) -> 3
N32: 001101 ภาษาอังกฤษ ***เวลาไม่แน่นอน*** | R32: 140104 | V32: 13110
C33: รวม | K33: =SUM(K26:K31) -> 18
N35: 001101 ภาษาอังกฤษ ***เวลาไม่แน่นอน*** | R35: 140104 | V35: 13110

Sheet ปี2 (รหัส67) เทอม1-68 (55)
A1: ตารางเรียนสาขาวิชาดิจิทัลเกม สำหรับนักศึกษาชั้นปีที่ 2 (รหัส67)
A2: ภาคการศึกษาที่ 1 ปีการศึกษา 2568
I3: (จำนวนนักศึกษา 55 คน)
B4: 08.00 | D4: 09.00 | F4: 10.00 | H4: 11.00 | J4: 12.00 | L4: 13.00 | N4: 14.00 | P4: 15.00 | R4: 16.00 | T4: 17.00 | V4: 18.00
A5: Monday | E5: 958201 MATH FOR COMP GRAPH & GAME 60 คน ผศ.ดร.กฤติยา (ฺB303) | H5: มช. มีการเปลี่ยนแปลงให้ 001201 เรียนในเทอม 2 Critical Reading and Effective Writing สำหรับเทอม 1 เรียน 001229 | O5: 955104 (Sec.001) 20 คน อ.ดร. ศุภรา (เปิดสำหรับเด็กตกค้าง รหัส 65) ILC - B202
L6: ฺ
A7: tuesday | E7: 958373 GAMIFICATION 30 คน ผศ.ดร.ธีรวัฒน์ b305 (Sec001) | H7: 958211 Data Structure for Game Development 60 คน ผศ.ดร.เกียรติกร b303 (Sec001) | L7: 958225 Digital Game Production sec.001 (อ.นพพล เปลี่ยนเป็น อ.ดร.ศุภรา เป็นผู้สอน) ILC - B302 ,C208 + C209
A9: wednesday | L9: 958261/001 GRAPHICS DESIGN FOR 2D GAMES 60คน อ.ปฏิสนธิ์ (อ.พิเศษ) (b303) | N9: 958261/001 อ.ปฏิสนธิ์ (อ.พิเศษ) GRAPHICS DESIGN FOR 2D GAMES (c207), /002 TA C208, /003ILC-C209 sec30คน
L11: 958205 Basic Game Design sec.001 (จำนวน 55 คน) (อ.มอง เป็นผู้สอน) CAMT 113,c207,c305 เดิม สอนวันศุกร์ ย้ายมาสอนเป็นวันพุธ ได้ห้อง C208+209 เนื่องจาก ห้องเรียนไม่เพียงพอ
A13: thursday | E13: 958201 MATH FOR COMP GRAPH & GAME 60 คน ผศ.ดร.กฤติยา (ฺB303) | H13: มช. มีการเปลี่ยนแปลงให้ 001201 เรียนในเทอม 2 Critical Reading and Effective Writing สำหรับเทอม 1 เรียน 001229 | L13: 958221 เปิดเป็น 2 Sec. 001/002 55 คน ผศ.ดร.ปฏิสนธิ์ (ฺB303) ขอใช้ห้อง COM C207/208-209 | N13: 958221 เปิดเป็น 2 Sec.001/002 ผศ.ดร.ปฏิสนธิ์ Lab.001 ได้ห้อง (C207 และ C208-209)
A15: Friday | E15: 958373 GAMIFICATION 30 คน ผศ.ดร.ธีรวัฒน์ b305 (Sec001) | H15: 958211 Data Structure for Game Development 60 คน ผศ.ดร.เกียรติกร b303 (Sec001) | L15: 958205 Basic Game Design sec.001 (จำนวน 55 คน) (อ.มอง เป็นผู้สอน) CAMT 113,c207,c305 เดิม สอนวันศุกร์ ย้ายมาสอนเป็นวันพุธ ได้ห้อง C208+209 หมายเหตุ : สอนวันเดิม (วันศุกร์) เพราะว่า ได้ห้องแล้วๆ (04/04/2025)
A19: Saturday
A20: Sunday
A24: สถานนะตรวจสอบ | B24: รายวิชา | K24: หน่วยกิต | L24: ผู้สอน | M24: ห้อง | N24: หมายเหตุ | U24: วิทยากร | X24: อาจารย์พิเศษ | Z24: TA | AB24: ชื่ออาจารย์ | AC24: เวลา ชม./สัปดาห์ | AD24: จำนวนสัปดาห์ | AE24: สรุปค่าตอบแทน
A25: ยังไม่ได้ตรวจสอบ | B25: 1 | C25: 001201 | D25: =VLOOKUP($C25,'DG2562V1.2Courses'!$B$4:$F$99,3,FALSE) -> Critical Reading and Effective Writing | K25: =VLOOKUP($C25,'DG2562V1.2Courses'!$B$4:$F$99,4,FALSE) -> 3 | U25: Lec (600) | V25: Lec (1000) | W25: Lec (1500) | X25: Lec (600) | Y25: Lab (450) | Z25: Lec (200) | AA25: Lab (200)
A26: ยังไม่ได้ตรวจสอบ | B26: 2 | C26: 955104 | D26: =VLOOKUP($C26,'DG2562V1.2Courses'!$B$4:$F$99,3,FALSE) -> Introduction to Digital Business | K26: =VLOOKUP($C26,'DG2562V1.2Courses'!$B$4:$F$99,4,FALSE) -> 2
A27: ยังไม่ได้ตรวจสอบ | B27: 3 | C27: 958201 | D27: =VLOOKUP($C27,'DG2562V1.2Courses'!$B$4:$F$99,3,FALSE) -> Mathematics for Computer Graphics and Game | K27: =VLOOKUP($C27,'DG2562V1.2Courses'!$B$4:$F$99,4,FALSE) -> 3 | L27: ผศ.ดร.กฤติยา | M27: b302
A28: ยังไม่ได้ตรวจสอบ | B28: 4 | C28: 958221 | D28: =VLOOKUP($C28,'DG2562V1.2Courses'!$B$4:$F$99,3,FALSE) -> Game Development 1 | K28: =VLOOKUP($C28,'DG2562V1.2Courses'!$B$4:$F$99,4,FALSE) -> 3 | L28: อ.ดร.ปฏิสนธิ์ | M28: C204,C206 | AA28: 1(น้องมาย)
A29: ยังไม่ได้ตรวจสอบ | B29: 5 | C29: 958225 | D29: =VLOOKUP($C29,'DG2562V1.2Courses'!$B$4:$F$99,3,FALSE) -> Digital Game Production | K29: =VLOOKUP($C29,'DG2562V1.2Courses'!$B$4:$F$99,4,FALSE) -> 3 | L29: อ.เอม | M29: B302, c204,c206
A30: ยังไม่ได้ตรวจสอบ | B30: 6 | C30: 958261 | D30: =VLOOKUP($C30,'DG2562V1.2Courses'!$B$4:$F$99,3,FALSE) -> Graphics Design for Two Dimensional Games | K30: =VLOOKUP($C30,'DG2562V1.2Courses'!$B$4:$F$99,4,FALSE) -> 3 | L30: อ.ศุภรา | X30: 1 | Y30: 1
C31: เอกเลือก | K31: 3 | N31: ***ให้นักศึกษาเลือกเพิ่ม
A32: ยังไม่ได้ตรวจสอบ | B32: 7 | C32: 958373 | D32: =VLOOKUP($C32,'DG2562V1.2Courses'!$B$4:$F$99,3,FALSE) -> Gamification | K32: 3 | L32: ผศ.ดร.ธีรวัฒน์ | M32: b302
A33: ยังไม่ได้ตรวจสอบ | K33: 3 | L33: อ.ดร.เทพฤทธิ์ | M33: C308 หรือ C309 | V33: 4ชม.
C34: รวม | K34: =SUM(K25:K31) -> 20
C35: ***หมายเหตุ*** สำหรับนักศึกษาที่ยังลงทะเบียนกลุ่มวิชาการเรียนรู้ผ่านกิจกรรม ไม่ครบ 3 หน่วยกิตต้องลงเพิ่มเติมให้ครบ

Sheet ปี3 (รหัส66) เทอม1-68 (66)
A1: ตารางเรียนสาขาวิชาดิจิทัลเกม สำหรับนักศึกษาชั้นปีที่ 3 (รหัส 66)
A2: ภาคการศึกษาที่ 1 ปีการศึกษา 2568
A3: (จำนวนนักศึกษา 47 คน) | G3: (จำนวนนักศึกษา 66 คน)
B4: 08.00 | D4: 09.00 | F4: 10.00 | H4: 11.00 | J4: 12.00 | L4: 13.00 | N4: 14.00 | P4: 15.00 | R4: 16.00 | T4: 17.00 | V4: 18.00
A5: Monday | L5: =C30 & "/001 " & D30 & " " & L30 & " " & M30 & " " & N30 & " คน " &O30 -> 958325/001 Artificial Intelligence for Game Development อ.ดร.ปฏิสนธิ์ C203,C204 - C206 75 คน เด็กตกแผน (รวมใน 75 คนแล้ว)
A7: tuesday | B7: (เอกเลือก) 958481/sec.003 C207 ได้ห้อง B201 หรือ C205 รอถาม อ.ก้อย ใช้ห้องไหน จำนวน 30 คน Sel Topic in Game Dev1 (Social Network Games) อ.ดร.สุมาลี | E7: (เอกเลือก) 958481/sec.002 จำนวน 66 คน Sel Topic in Game Dev1 (Basic Game Design) อ.ดร.ศุภรา lab C203, C204 - C206 | L7: 951212 3D Modeling and Animation Design 2 อ.ดร.กลวัชร ได้ห้อง C205 | N7: 951212 3D Modeling and Animation Design 2 อ.กลวัชร (Sec. 030, C205)
L9: (เอกเลือก) จำนวน 30 คน กระบวนวิชา 958481 (ตอนที่ 002) Sel Topic in Game Dev1 ( prog patterns ) อ.ดร.เกียรติกร (C309) ย้ายไปห้อง C307
D11: (เอกเลือก) ขวัญ PR ยังไม่ได้ติดต่อมาหา อ.จอห์น 958481/sec.006 เวลาเรียน และห้องเรียน TBA. จำนวน 15 คน Sel Topic in Game Dev1 (E-sport management or activity) อ.ดร.เทพฤทธิ์ | L11: 958331 (Lec)/sec.001 จำนวน 66 คน Database and Network for Game Dev อ.ดร.สุมาลี C203, C204- C206 ย้ายไปสอนเช้าๆๆๆ | N11: 958331 (Lab)/sec.001/sec.002 จำนวน 66 คน Database and Network for Game Dev อ.ดร.สุมาลี C203, C204- C206 ย้ายไปสอนเช้าๆๆๆ
A13: wednesday | B13: 958331 (Lec)/sec.001 จำนวน 66 คน Database and Network for Game Dev อ.ดร.สุมาลี C203, C204- C206 | D13: 958331 (Lab)/sec.001/sec.002 จำนวน 66 คน Database and Network for Game Dev อ.ดร.สุมาลี C203, C204- C206
A15: thursday | B15: (เอกเลือก) จำนวน 30 คน 958341 Realistic Game Development อ.ดร.เกียรติกร (C309) | L15: =C29 & "/sec.001 " & D29 & " " &L29 & " " & N29 & " คน " & M29 & " " & O29 -> 958321/sec.001 Game Development 3 อ.ดร.เกียรติกร 66 คน C203, C204-C206 | N15: 958321/001 (C203, C204-C206) Game Development 3 อ.ดร.เกียรติกร Sec 66 คน
A19: Friday | B19: (เอกเลือก) 958481/sec.003 C207 ได้ห้อง B201 จำนวน 30 คน Sel Topic in Game Dev1 (Social Network Games) อ.ดร.สุมาลี | E19: (เอกเลือก) 958481/sec.001 C305 จำนวน 30 คน ปรับแก้ไข จำนวน จาก 30 คน เป็น 25 คน (19 พค.68) Sel Topic in Game Dev1 (Virtual Reality) (VR) อ.ดร.เทพฤทธิ์ | L19: (เอกเลือก) 958481/sec.004 C305 จำนวน 30 คน Sel Topic in Game Dev1 (Adv UE) Unreal Engine5 อ.ดร.เทพฤทธิ์
L21: (เอกเลือก) 958441 (รับเด็ก 30 คน) Motion Capture for Game Development ผศ.ดร.ธีรวัฒน์ (112) | N21: (เอกเลือก) 958441 LAB / 001 (จำนวนที่รองรับได้ 30 คน) Motion Capture for Game Development ผศ.ดร.ธีรวัฒน์ (Lab : 309)
A23: Saturday
A24: Sunday
S27: วิทยากร | V27: อาจารย์พิเศษ | X27: TA | Z27: ชื่ออาจารย์ | AA27: เวลา ชม./สัปดาห์ | AB27: จำนวนสัปดาห์ | AC27: สรุปค่าตอบแทน
A28: สถานนะตรวจสอบ | D28: เอกบังคับ | E28: รายวิชา | L28: ผู้สอน | M28: ห้อง | N28: จำนวนรับ Sec001 | O28: หมายเหตุ | S28: Lec (600) | T28: Lec (1000) | U28: Lec (1500) | V28: Lec (600) | W28: Lab (450) | X28: Lec (200) | Y28: Lab (200)
A29: ยังไม่ได้ตรวจสอบ | B29: 1 | C29: 958321 | D29: Game Development 3 | J29: 3 | K29: 001 | L29: อ.ดร.เกียรติกร | M29: C203, C204-C206 | N29: 66
A30: ยังไม่ได้ตรวจสอบ | B30: 2 | C30: 958325 | D30: Artificial Intelligence for Game Development | J30: 3 | K30: 001 | L30: อ.ดร.ปฏิสนธิ์ | M30: C203,C204 - C206 | N30: 75 | O30: เด็กตกแผน (รวมใน 75 คนแล้ว)
A31: ยังไม่ได้ตรวจสอบ | B31: 3 | C31: 958331 | D31: Database and Network for Game Development | J31: 3 | K31: 001 | L31: อ.ดร. สุมาลี | M31: C206,C207 | N31: 60 (ห้องรับได้ถึง 68) | O31: เด็กตกแผนเพิ่มมา 13 คน (รวมใน 60 คนแล้ว) | T31: 1คน 3ชม.
B32: ***ให้นักศึกษาเลือกเพิ่ม | D32: เอกเลือก | J32: 6
A33: ยังไม่ได้ตรวจสอบ | C33: 958341 | D33: Realistic Game Development (เอกเลือก) | J33: 3 | K33: 001 | L33: อ.ดร.เกียรติกร | M33: C309 | N33: 30 | O33: ปิดกระบวนวิชา
A34: ยังไม่ได้ตรวจสอบ | B34: 4 | C34: 958481 | J34: 3 | K34: 002 | L34: อ.ดร.เกียรติกร | M34: C309 | N34: 30 | O34: เปิดกระบวนวิชานี้แทน
A35: ยังไม่ได้ตรวจสอบ | B35: 5 | C35: 958441 | D35: Motion Capture for Game Development(เอกเลือก) | J35: 3 | K35: 001 | L35: ผศ.ดร.ธีรวัฒน์ | M35: 112 ,C309 | N35: 30 | T35: 1คน 10ชม.(2ครั้ง)
A36: ตรวจสอบแล้ว (เทพฤทธิ์) | B36: 6 | C36: 958481 | D36: Sel Topic in Game Dev1 (AdvUE) | J36: 3 | K36: 001 | L36: อ.ดร.เทพฤทธิ์ | M36: XXX | N36: 25
A37: ยังไม่ได้ตรวจสอบ | B37: 7 | C37: 958481 | D37: Sel Topic in Game Dev1 (Basic Game Design) (เอกเลือก) | J37: 3 | K37: 003 | L37: อ.ศุภรา | M37: B302 | N37: 59 | X37: 1(น้องยู้)
A38: ยังไม่ได้ตรวจสอบ | B38: 8 | C38: 951212 | D38: Three Dimensional Modeling and Animation Design 2 | J38: 3 | K38: 001 | L38: อ.ดร.กลวัชร | M38: C205 | N38: 25 | O38: 1/69 เปลี่ยนรหัส ให้เปิดกระบวนวิชา 958263
C39: รวม | J39: =SUM(J29:J32) -> 15
C40: ***หมายเหตุ*** สำหรับนักศึกษาที่ยังลงทะเบียนกลุ่มวิชาการเรียนรู้ผ่านกิจกรรม ไม่ครบ 3 หน่วยกิตต้องลงเพิ่มเติมให้ครบ
C47: test | D47: =C29 & " " & D29 -> 958321 Game Development 3

Sheet สำเนาของ ปี2 (รหัส66) เทอม1-67 
A1: ตารางเรียนสาขาวิชาดิจิทัลเกม สำหรับนักศึกษาชั้นปีที่ 2 (รหัส66)
A2: ภาคการศึกษาที่ 1 ปีการศึกษา 2567
I3: (จำนวนนักศึกษา 65 คน)
B4: 08.00 | D4: 09.00 | F4: 10.00 | H4: 11.00 | J4: 12.00 | L4: 13.00 | N4: 14.00 | P4: 15.00 | R4: 16.00 | T4: 17.00 | V4: 18.00
A5: Monday | E5: 958201 MATH FOR COMP GRAPH & GAME 80 คน ผศ.ดร.กฤติยา CAMT 113 | H5: 001201 Critical Reading and Effective Writing | O5: 955104 (Sec.001) 60คน อ.ศุภรา 113
A7: tuesday | H7: 958373 GAMIFICATION 30 คน ผศ.ดร.ธีรวัฒน์ b302 (Sec001) | L7: 958225 Digital Game Production sec.001 อ.ศุภรา (อ.เอม เป็นผู้สอน) c201,c202
A9: wednesday | L9: 958261/001 GRAPHICS DESIGN FOR 2D GAMES 60คน อ.ศุภรา (อ.พิเศษ) (b302) | N9: 958261/001 อ.ศุภรา (อ.พิเศษ) GRAPHICS DESIGN FOR 2D GAMES (c207), /002 TA C208, /003ILC-C209 sec30คน
A11: thursday | E11: 958201 MATH FOR COMP GRAPH & GAME 80 คน ผศ.ดร.กฤติยา CAMT 113 | H11: 001201 Critical Reading and Effective Writing | L11: 958221/001 60คน อ.ดร.ปฏิสนธิ์ (b302) | N11: 958221/001 อ.ดร.ปฏิสนธิ์ (c204), /002 TA (c206), sec30คน
A13: Friday | H13: 958373 GAMIFICATION 30 คน ผศ.ดร.ธีรวัฒน์ b302 (Sec001)
A17: Saturday
A18: Sunday
A22: สถานนะตรวจสอบ | B22: รายวิชา | K22: หน่วยกิต | L22: ผู้สอน | M22: ห้อง | N22: หมายเหตุ | U22: วิทยากร | X22: อาจารย์พิเศษ | Z22: TA | AB22: ชื่ออาจารย์ | AC22: เวลา ชม./สัปดาห์ | AD22: จำนวนสัปดาห์ | AE22: สรุปค่าตอบแทน
A23: ยังไม่ได้ตรวจสอบ | B23: 1 | C23: 001201 | D23: =VLOOKUP($C23,'DG2562V1.2Courses'!$B$4:$F$99,3,FALSE) -> Critical Reading and Effective Writing | K23: =VLOOKUP($C23,'DG2562V1.2Courses'!$B$4:$F$99,4,FALSE) -> 3 | U23: Lec (600) | V23: Lec (1000) | W23: Lec (1500) | X23: Lec (600) | Y23: Lab (450) | Z23: Lec (200) | AA23: Lab (200)
A24: ยังไม่ได้ตรวจสอบ | B24: 2 | C24: 955104 | D24: =VLOOKUP($C24,'DG2562V1.2Courses'!$B$4:$F$99,3,FALSE) -> Introduction to Digital Business | K24: =VLOOKUP($C24,'DG2562V1.2Courses'!$B$4:$F$99,4,FALSE) -> 2
A25: ยังไม่ได้ตรวจสอบ | B25: 3 | C25: 958201 | D25: =VLOOKUP($C25,'DG2562V1.2Courses'!$B$4:$F$99,3,FALSE) -> Mathematics for Computer Graphics and Game | K25: =VLOOKUP($C25,'DG2562V1.2Courses'!$B$4:$F$99,4,FALSE) -> 3 | L25: ผศ.ดร.กฤติยา | M25: b302
A26: ยังไม่ได้ตรวจสอบ | B26: 4 | C26: 958221 | D26: =VLOOKUP($C26,'DG2562V1.2Courses'!$B$4:$F$99,3,FALSE) -> Game Development 1 | K26: =VLOOKUP($C26,'DG2562V1.2Courses'!$B$4:$F$99,4,FALSE) -> 3 | L26: อ.ดร.ปฏิสนธิ์ | M26: C207,C208 | AA26: 1(น้องมาย)
A27: ยังไม่ได้ตรวจสอบ | B27: 5 | C27: 958225 | D27: =VLOOKUP($C27,'DG2562V1.2Courses'!$B$4:$F$99,3,FALSE) -> Digital Game Production | K27: =VLOOKUP($C27,'DG2562V1.2Courses'!$B$4:$F$99,4,FALSE) -> 3 | L27: อ.ศุภรา (เอมสอน) | M27: c201,c202
A28: ยังไม่ได้ตรวจสอบ | B28: 6 | C28: 958261 | D28: =VLOOKUP($C28,'DG2562V1.2Courses'!$B$4:$F$99,3,FALSE) -> Graphics Design for Two Dimensional Games | K28: =VLOOKUP($C28,'DG2562V1.2Courses'!$B$4:$F$99,4,FALSE) -> 3 | L28: อ.ศุภรา | X28: 1 | Y28: 1
C29: เอกเลือก | K29: 3 | N29: ***ให้นักศึกษาเลือกเพิ่ม
A30: ยังไม่ได้ตรวจสอบ | B30: 7 | C30: 958373 | D30: =VLOOKUP($C30,'DG2562V1.2Courses'!$B$4:$F$99,3,FALSE) -> Gamification | K30: 3 | L30: ผศ.ดร.ธีรวัฒน์ | M30: b302
A31: ยังไม่ได้ตรวจสอบ | K31: 3 | L31: อ.ดร.เทพฤทธิ์ | M31: C308 หรือ C309 | V31: 4ชม.
C32: รวม | K32: =SUM(K23:K29) -> 20
C33: ***หมายเหตุ*** สำหรับนักศึกษาที่ยังลงทะเบียนกลุ่มวิชาการเรียนรู้ผ่านกิจกรรม ไม่ครบ 3 หน่วยกิตต้องลงเพิ่มเติมให้ครบ

Sheet สำเนาของ ปี3 (รหัส65) เทอม1-67 
A1: ตารางเรียนสาขาวิชาดิจิทัลเกม สำหรับนักศึกษาชั้นปีที่ 3 (รหัส 65)
A2: ภาคการศึกษาที่ 1 ปีการศึกษา 2567
A3: (จำนวนนักศึกษา 47 คน) | G3: (จำนวนนักศึกษา 58 คน)
B4: 08.00 | D4: 09.00 | F4: 10.00 | H4: 11.00 | J4: 12.00 | L4: 13.00 | N4: 14.00 | P4: 15.00 | R4: 16.00 | T4: 17.00 | V4: 18.00
A5: Monday | E5: (เอกเลือก) 958481/sec.003 (ฺCAMT 112) Sel Topic in Game Dev1 (Basic Game Design) อ.ศุภรา lab notebook C305,C306 | L5: =C26 & "/001 " & D26 & " " & L26 & " " & M26 & " " & N26 & " คน " &O26 -> 958325/001 Artificial Intelligence for Game Development อ.ดร.ปฏิสนธิ์ C308,C309 60 คน เด็กตกแผนเพิ่มมา 13 คน (รวมใน 60 คนแล้ว)
A7: tuesday | E7: (เอกเลือก) 958481/sec.001 C308 Sel Topic in Game Dev1 (Adv UE ) อ.ดร.เทพฤทธิ์ | L7: 951212 3D Modeling and Animation Design 2 อ.ดร.กลวัชร (C204) ได้ห้อง C209 | N7: 951212 3D Modeling and Animation Design 2 อ.กลวัชร (Sec. 030, C209)
E9: (เอกเลือก) 958481/sec.004 C309 Sel Topic in Game Dev1 (Adv UE ) อ.ดร.เทพฤทธิ์
A11: wednesday | L11: 958331/sec.001 Database and Network for Game Development อ.ดร.สุมาลี lec.113 (lab C204,c206) ได้ห้อง c203/c204
A13: thursday | E13: (เอกเลือก) 958341 (ปิดกระบวนวิชานี้) แล้วเปิดกระบวนวิชา 958481 (ตอนที่ 002) Realistic Game Sel Topic in Game prog patterns Development อ.ดร.เกียรติกร (C309) | L13: =C25 & "/sec.001 " & D25 & " " &L25 & " " & N25 & " คน " & M25 & " " & O25 -> 958321/sec.001 Game Development 3 อ.ดร.เกียรติกร 58 คน C308,C309,307 เด็กตกแผนเพิ่มมา 13 คน | N13: 958321/001 (C307) Game Development 3 อ.ดร.เกียรติกร Sec.002/(C308), TA Sec.003 (C309),อานน Sec 25 คน
B15: (เอกเลือก) 958441 Motion Capture for Game Development ผศ.ดร.ธีรวัฒน์ (112) | D15: (เอกเลือก) 958441 LAB / 001 (จำนวนที่รองรับได้ 30 คน) Motion Capture for Game Development ผศ.ดร.ธีรวัฒน์ (C202) แลกห้องกับ อ.แนท SE เป็นห้อง C206 เรียบร้อยแล้ว
A17: Friday | E17: (เอกเลือก) 958481/sec.001 C205 (เดิมเป็น C308) Sel Topic in Game Dev1 (Adv UE ) อ.ดร.เทพฤทธิ์ | L17: (เอกเลือก) 958481/sec.004 C205 (เดิมเป็น C308) Sel Topic in Game Dev1 (VR) อ.ดร.เทพฤทธิ์
A19: Saturday
A20: Sunday
S23: วิทยากร | V23: อาจารย์พิเศษ | X23: TA | Z23: ชื่ออาจารย์ | AA23: เวลา ชม./สัปดาห์ | AB23: จำนวนสัปดาห์ | AC23: สรุปค่าตอบแทน
A24: สถานนะตรวจสอบ | D24: เอกบังคับ | E24: รายวิชา | L24: ผู้สอน | M24: ห้อง | N24: จำนวนรับ Sec001 | O24: หมายเหตุ | S24: Lec (600) | T24: Lec (1000) | U24: Lec (1500) | V24: Lec (600) | W24: Lab (450) | X24: Lec (200) | Y24: Lab (200)
A25: ยังไม่ได้ตรวจสอบ | B25: 1 | C25: 958321 | D25: Game Development 3 | J25: 3 | K25: 001 | L25: อ.ดร.เกียรติกร | M25: C308,C309,307 | N25: 58 | O25: เด็กตกแผนเพิ่มมา 13 คน
A26: ยังไม่ได้ตรวจสอบ | B26: 2 | C26: 958325 | D26: Artificial Intelligence for Game Development | J26: 3 | K26: 001 | L26: อ.ดร.ปฏิสนธิ์ | M26: C308,C309 | N26: =47+13 -> 60 | O26: เด็กตกแผนเพิ่มมา 13 คน (รวมใน 60 คนแล้ว)
A27: ยังไม่ได้ตรวจสอบ | B27: 3 | C27: 958331 | D27: Database and Network for Game Development | J27: 3 | K27: 001 | L27: อ.ดร. สุมาลี | M27: C206,C207 | N27: 60 (ห้องรับได้ถึง 68) | O27: เด็กตกแผนเพิ่มมา 13 คน (รวมใน 60 คนแล้ว) | T27: 1คน 3ชม.
B28: ***ให้นักศึกษาเลือกเพิ่ม | D28: เอกเลือก | J28: 6
A29: ยังไม่ได้ตรวจสอบ | C29: 958341 | D29: Realistic Game Development (เอกเลือก) | J29: 3 | K29: 001 | L29: อ.ดร.เกียรติกร | M29: C309 | N29: 30 | O29: ปิดกระบวนวิชา
A30: ยังไม่ได้ตรวจสอบ | B30: 4 | C30: 958481 | J30: 3 | K30: 002 | L30: อ.ดร.เกียรติกร | M30: C309 | N30: 30 | O30: เปิดกระบวนวิชานี้แทน
A31: ยังไม่ได้ตรวจสอบ | B31: 5 | C31: 958441 | D31: Motion Capture for Game Development(เอกเลือก) | J31: 3 | K31: 001 | L31: ผศ.ดร.ธีรวัฒน์ | M31: 112 ,C202,C206 | N31: 30 | T31: 1คน 10ชม.(2ครั้ง)
A32: ตรวจสอบแล้ว (เทพฤทธิ์) | B32: 6 | C32: 958481 | D32: Sel Topic in Game Dev1 (AdvUE) | J32: 3 | K32: 001 | L32: อ.ดร.เทพฤทธิ์ | M32: XXX | N32: 25
A33: ยังไม่ได้ตรวจสอบ | B33: 7 | C33: 958481 | D33: Sel Topic in Game Dev1 (Basic Game Design) (เอกเลือก) | J33: 3 | K33: 003 | L33: อ.ศุภรา | M33: B302 | N33: 59 | X33: 1(น้องยู้)
A34: ยังไม่ได้ตรวจสอบ | B34: 8 | C34: 951212 | D34: Three Dimensional Modeling and Animation Design 2 | J34: 3 | K34: 001 | L34: อ.ดร.อรุษ | M34: C208 | N34: 25
C35: รวม | J35: =SUM(J25:J28) -> 15
C36: ***หมายเหตุ*** สำหรับนักศึกษาที่ยังลงทะเบียนกลุ่มวิชาการเรียนรู้ผ่านกิจกรรม ไม่ครบ 3 หน่วยกิตต้องลงเพิ่มเติมให้ครบ
C43: test | D43: =C25 & " " & D25 -> 958321 Game Development 3

Sheet ตารางเปรียบเทียบเวลาเรียน
A1: ตารางเปรียบเทียบเวลาเรียน นักศึกษาสาขาวิชาดิจิทัลเกม (DG)
A2: วัน | B2: ชั้นปี | C2: 0.33333333 | D2: 0.35416667 | E2: 0.375 | F2: 0.39583333 | G2: 0.41666667 | H2: 0.4375 | I2: 0.45833333 | J2: 0.47916667 | K2: 0.5 | L2: 0.52083333 | M2: 0.54166667 | N2: 0.5625 | O2: 0.58333333 | P2: 0.60416667 | Q2: 0.625 | R2: 0.64583333 | S2: 0.66666667 | T2: 0.6875 | U2: 0.70833333 | V2: 0.72916667 | W2: 0.75
A3: จันทร์ | B3: ปี 1 (56 คน) | F3: 013110 Psychology and Daily Life | I3: 001101 Fundamental English 1
B4: ปี 2 (55 คน) | F4: 958201 MATH FOR COMP GRAPH & GAME ผศ.ดร.กฤติยา · 60 คน · B303 | I4: 001229 English for Media Arts (เทอม 1) | P4: 955104 (Sec.001) อ.ดร.ศุภรา · 20 คน (เด็กตกค้าง รหัส 65) ·ILC B202
B5: ปี 3 (56 คน) | M5: 958325/001 Artificial Intelligence for Game Development อ.ดร.ปฏิสนธิ์ · 75 คน · C203, C204-C206
B6: ปี 4 (48 คน) | C6: 958491 Work Integrated Learning for Digital Game 1 (สหกิจศึกษา 9 หน่วยกิต) — ไม่มีคาบเรียนตายตัว
A7: อังคาร | B7: ปี 1 (56 คน) | F7: 801100 Architecture in Everyday Life | I7: 140104 Citizenship | M7: 958102/001 Introduction to Digital Games ผศ.ดร.ธีรวัฒน์ 60 คน ILC B304+B306
B8: ปี 2 (55 คน) | I8: 958211 Data Structure for Game Development ผศ.ดร.เกียรติกร 60 คน B303 (Sec001) | M8: 958225 Digital Game Production (Sec.001) อ.ดร.ศุภรา ILC B302, C208+C209
B9: ปี 3 (56 คน) | C9: 958481/003 (เอกเลือก) Sel Topic in Game Dev1 (Social Network Games) อ.ดร.สุมาลี · 30 คน · B201 | F9: 958481/sec.002 (เอกเลือก) Sel Topic in Game Dev1 (Basic Game Design) อ.ดร.ศุภรา · 66 คน · lab C203, C204 - C206 | M9: 951212 3D Modeling and Animation Design 2 (Lec) อ.ดร.กลวัชร · C205 | O9: 951212 3D Modeling and Animation Design 2 (Lab) อ.ดร.กลวัชร · C205
B10: ปี 4 (48 คน) | C10: 958491 Work Integrated Learning for Digital Game 1 (สหกิจศึกษา 9 หน่วยกิต) — ไม่มีคาบเรียนตายตัว
A11: พุธ | B11: ปี 1 (56 คน) | M11: 958111/001 & /002 COMP & PROGRAM FOR GAME 1 (Lec) /001 ผศ.ดร.กฤติยา · /002 ผศ.ดร.ธีรวัฒน์ ILC B304-306 | O11: 958111/001 & /002 COMP & PROGRAM FOR GAME 1 (Lab) LAB C204+C206
B12: ปี 2 (55 คน)
B13: ปี 3 (56 คน) | C13: 958331 (Lec)/sec.001 Database and Network for Game Dev 66 คน · อ.ดร.สุมาลี · C203, C204-C206 | E13: 958331 (Lab)/sec.001/sec.002 Database and Network for Game Dev อ.ดร.สุมาลี · 66 คน · lab C203, C204 - C206
B14: ปี 4 (48 คน) | C14: 958491 Work Integrated Learning for Digital Game 1 (สหกิจศึกษา 9 หน่วยกิต) — ไม่มีคาบเรียนตายตัว
A15: พฤหัสบดี | B15: ปี 1 (56 คน) | F15: 013110 Psychology and Daily Life | I15: 001101 Fundamental English 1
B16: ปี 2 (55 คน) | F16: 958201 MATH FOR COMP GRAPH & GAME 60 คน ผศ.ดร.กฤติยา B303 | I16: 001229 Critical Reading & Effective Writing (เทอม 1) | M16: 958221 (Lec) เปิด 2 Sec. 001/002 55 คน · ผศ.ดร.ปฏิสนธิ์ · B303 / C207, C208-209 | O16: 958221 (Lab)/sec.001-002 ผศ.ดร.ปฏิสนธิ์ C207, C208-209
B17: ปี 3 (56 คน) | M17: 958321/sec.001 Game Development 3 (Lec) 66 คน · อ.ดร.เกียรติกร · C203, C204-C206 | O17: 958321/sec.001 Game Development 3 (Lab) 66 คน · อ.ดร.เกียรติกร · C203, C204-C206
B18: ปี 4 (48 คน) | C18: 958491 Work Integrated Learning for Digital Game 1 (สหกิจศึกษา 9 หน่วยกิต) — ไม่มีคาบเรียนตายตัว
A19: ศุกร์ | B19: ปี 1 (56 คน) | F19: 801100 Architecture in Everyday Life | I19: 140104 Citizenship | M19: 958102/001 Introduction to Digital Games 60 คน อ.เอ๋ · ILC B304+306 (เรียนยาว 3 ชม. วันอังคารแทน)
B20: ปี 2 (55 คน) | I20: 958211 Data Structure for Game Development 60 คน · ผศ.ดร.เกียรติกร · B303 | M20: 958205 Basic Game Design (Sec.001) 55 คน · อ.มอง · 113, C207, C305
B21: ปี 3 (56 คน) | C21: 958481/003 (เอกเลือก) Sel Topic in Game Dev1 (Social Network Games) 30 คน · อ.ดร.สุมาลี · B201 | F21: 958481/sec.001 (เอกเลือก) Sel Topic in Game Dev1 (Virtual Reality) (VR) อ.ดร.เทพฤทธิ์ · 25 คน · C305 | M21: 958481/004 (เอกเลือก) Sel Topic (Adv UE5) อ.ดร.เทพฤทธิ์ · C305 · 30 คน
M22: 958441 (เอกเลือก) (Lec)/001 Motion Capture for Game Development 30 คน · ผศ.ดร.ธีรวัฒน์ · 112 | O22: 958441 (เอกเลือก) (Lab)/001 Motion Capture for Game Development 30 คน · ผศ.ดร.ธีรวัฒน์ · Lab 309
B23: ปี 4 (48 คน) | C23: 958491 Work Integrated Learning for Digital Game 1 (สหกิจศึกษา 9 หน่วยกิต) — ไม่มีคาบเรียนตายตัว

Sheet ปี4 (รหัส65) เทอม1-68 (48)
A1: ตารางเรียนสาขาวิชาดิจิทัลเกม สำหรับนักศึกษาชั้นปีที่ 4 (รหัส65)
A2: ภาคการศึกษาที่ 1 ปีการศึกษา 2568
A3: (จำนวนนักศึกษา 48 คน)
B4: 08.00 | D4: 09.00 | F4: 10.00 | H4: 11.00 | J4: 12.00 | L4: 13.00 | N4: 14.00 | P4: 15.00 | R4: 16.00 | T4: 17.00 | V4: 18.00
A5: Monday
A7: tuesday
A9: wednesday
A11: thursday
A15: Friday
A17: Saturday
A18: Sunday
B21: Section | R21: วิทยากร | U21: อาจารย์พิเศษ | W21: TA | Y21: ชื่ออาจารย์ | Z21: เวลา ชม./สัปดาห์ | AA21: จำนวนสัปดาห์ | AB21: สรุปค่าตอบแทน
B22: รายวิชา | K22: หน่วยกิต | L22: ผู้สอน | M22: ห้อง | N22: คน | O22: หมายเหตุ | R22: Lec (600) | S22: Lec (1000) | T22: Lec (1500) | U22: Lec (600) | V22: Lab (450) | W22: Lec (200) | X22: Lab (200)
B23: 1 | C23: 958491 | D23: Work integrated Lerning for Digital Game 1 | K23: 9 | L23: อ. เกียรติกร | N23: 10
B24: 2 | C24: 958491 | L24: อ. เอ๋ | N24: 10
B25: 3 | C25: 958491 | L25: อ. แจ๋ว | N25: 10
B26: 4 | C26: 958491 | L26: อ. น้อย | N26: 10
B27: 5 | C27: 958491 | L27: อ. จอน | N27: 10
B28: 7 | C28: 958491 | L28: อ. สุมาลี | N28: 10
B29: 8 | C29: 958491 | L29: อ. มอง | N29: 10
B30: 9 | C30: 958491 | L30: อ.เอม | N30: 10
C32: รวม | K32: =SUM(K23:K31) -> 9
C33: ***หมายเหตุ*** สำหรับนักศึกษาที่ยังลงทะเบียนกลุ่มวิชาการเรียนรู้ผ่านกิจกรรม ไม่ครบ 3 หน่วยกิตต้องลงเพิ่มเติมให้ครบ

Sheet Workload
A1: รายละเอียดข้อมูล ภาระงานสอนของอาจารย์ในสาขาวิชาดิจิทัลเกม ในภาคการศึกษาที่ 1 ปีการศึกษา 2568
A3: ชื่ออาจารย์ผู้สอน | B3: จำนวนกระบวนวิชาที่สอน | C3: รหัสกระบวนวิชา | D3: สอนนักศึกษาชั้นปีที่ | E3: จำนวนนักศึกษา (คน) | F3: โครงสร้างหลักสูตร | I3: ผศ.ดร.เกียรติกร | J3: ผศ.ดร.ธีรวัฒน์ | K3: อ.ดร.ศุภรา | L3: ผศ.ดร.กฤติยา | M3: ผศ.ดร.ปฏิสนธิ์ | N3: ผศ.ดร.สุมาลี | O3: อ.ดร.เทพฤทธิ์ | P3: อ.นพพล
A4: ผศ.ดร.เกียรติกร | B4: 2 | C4: - 958211 : DATA STRUCTURE FOR GAME DEVELOPMENT | D4: 2 | E4: 56 | F4: หมวดวิชาแกน | H4: จำนวนวิชา | I4: =B4 -> 2 | J4: =B6 -> 3 | K4: =B9 -> 4 | L4: =B13 -> 2 | M4: =B15 -> 2 | N4: =B17 -> 2 | O4: =B19 -> 2 | P4: =B21 -> 0
C5: - 958321 : GAME DEVELOPMENT 3 | D5: 3 | E5: 66 | F5: วิชาเอกบังคับ | H5: WIL | I5: 1 | J5: 1 | K5: 1 | L5: 1 | M5: 1 | N5: 1 | O5: 1 | P5: 0
A6: ผศ.ดร.ธีรวัฒน์ | B6: 3 | C6: - 958111 : COMP & PROGRAM FOR GAME 1 (Sec.002) | D6: 1 | E6: 55 | F6: หมวดวิชาแกน | H6: รวม | I6: =I4+I5 -> 3 | J6: =J4+J5 -> 4 | K6: =K4+K5 -> 5 | L6: =L4+L5 -> 3 | M6: =M4+M5 -> 3 | N6: =N4+N5 -> 3 | O6: =O4+O5 -> 3 | P6: =P4+P5 -> 0
C7: - 958102 : INTRODUCTION TO DIGITAL GAMES | D7: 1 | E7: 56 | F7: หมวดวิชาแกน
C8: - 958441 : MOTION CAPTURE FOR GAME DEVELOPMENT | D8: 3 | E8: 30 | F8: วิชาเอกเลือก
A9: อ.ดร.ศุภรา | B9: 4 | C9: - 955104 : INTRODUCTION TO DIGITAL BUSINESS | D9: ทุกชั้นปีที่ตกค้าง (หลักสูตร พ.ศ.2562) | E9: 5 | F9: หมวดวิชาแกน
C10: - 958205 : BASIC GAME DESIGN | D10: 2 | E10: 55 | F10: วิชาเอกบังคับ
C11: - 958225 : DIGITAL GAME PRODUCTION สอน นศ.ชั้นปีที่ 2 (55 คน) วิชาเอกบังคับ | D11: 2 | E11: 55 | F11: วิชาเอกบังคับ
C12: - 958481 : SELECTED TOPICS IN GAME DEVELOPMENT1 (BASIC GAME DESIGN) sec.002 | D12: 3 | E12: 66 | F12: วิชาเอกเลืือก
A13: ผศ.ดร.กฤติยา | B13: 2 | C13: - 958111 : COMP & PROGRAM FOR GAME 1 (Sec.001) | D13: 1 | E13: 56 | F13: หมวดวิชาแกน
C14: - 958201 : MATH FOR COMP GRAPH & GAME | D14: 2 | E14: 55 | F14: หมวดวิชาแกน
A15: ผศ.ดร.ปฏิสนธิ์ | B15: 2 | C15: - 958221 : GAME DEVELOPMENT 1 | D15: 2 | E15: 22 | F15: วิชาเอกบังคับ
C16: - 958325 : ARTIFICAIAL INTELLIGENCE FOR GAME DEVELOPMENT | D16: 3 และเด็กตกแผน | E16: 75 | F16: วิิชาเอกบังคับ
A17: ผศ.ดร.สุมาลี | B17: 2 | C17: - 958331 : DATABASE AND NETWORK FOR GAME DEV | D17: 3 | E17: 66 | F17: วิชาเอกบังคับ
C18: - 958481 : SELECTED TOPICS IN GAME DEVELOPMENT1 (ADV HYPER CASUAL GAMES) sec.003 | D18: 3 | E18: 30 | F18: วิชาเอกเลือก
A19: อ.ดร.เทพฤทธิ์ | B19: 2 | C19: - 958481 : SELECTED TOPICS IN GAME DEVELOPMENT1 (VIRTUAL REALITY) sec.001 | D19: 3 | E19: 30 | F19: วิชาเอกเลือก
C20: - 958481 : SELECTED TOPICS IN GAME DEVELOPMENT1 (ADV UE) UNREAL ENGINE sec.004 | D20: 3 | E20: 30 | F20: วิชาเอกเลือก
A21: อ.นพพล | B21: 0 | C21: ลาศึกษาต่อ

Sheet DG2562V1.2Courses
B1: (1) General Education
B2: Course Code | C2: Course Abbrev | D2: Course Name | E2: Course Credits | F2: Credits Structure
B3: 1.1 Required Courses
B4: 001101 | C4: ENGL 101 | D4: Fundamental English 1 | E4: 3 | F4: 3-0-6
B5: 001102 | C5: ENGL 102 | D5: Fundamental English 2 | E5: 3 | F5: 3-0-6
B6: 001201 | C6: ENGL 201 | D6: Critical Reading and Effective Writing | E6: 3 | F6: 3-0-6
B7: 001229 | C7: ENGL 229 | D7: English for Media Arts | E7: 3 | F7: 3-0-6
B8: 261111 | D8: Internet and Online Community | E8: 3
B9: 1.2 Innovative Co-Creator
B10: 013110 | C10: PSY 100 | D10: Psychology and Daily Life | E10: 3 | F10: 3-0-6
B11: 206100 | D11: Mathematics in Everyday Life | E11: 3
B12: 356102 | D12: Ornamental Aquatic Animals | E12: 3
B13: 852100 | D13: Introduction to Film | E13: 3
B14: 888107 | D14: Business Startup on Digital Platform | E14: 3
B15: 1.3 Active Citizen
B16: 140104 | D16: Citizenship | E16: 3
B17: 1.4 Elective Courses
B18: 057137 | D18: Sports for Health | E18: 3
B19: 011155 | D19: Philosophy of Happiness | E19: 3
B20: 011100 | D20: Man and Philosophy | E20: 3
B21: 012200 | D21: Mind Volunteer | E21: 3
B22: 154100 | D22: Introduction to Geography | E22: 3
B23: 259108 | D23: Electricity in Everyday Life | E23: 3
B24: 801100 | D24: Architecture in Everyday Life | E24: 3
B25: (2) Field of Specialization
B26: (2.1) Core Courses
B27: 955102 | D27: Digital Literacy | E27: 2 | F27: 1-2-3
B28: 955103 | D28: Programming and Logical Thinking | E28: 2 | F28: 1-2-3
B29: 955104 | D29: Introduction to Digital Business | E29: 2 | F29: 2-0-4
B30: 955105 | D30: Fundamental Design in Digital Arts | E30: 2 | F30: 1-2-3
B31: 958111 | D31: Computer and Programming for Game 1 | E31: 3 | F31: 1-4-4
B32: 958112 | D32: Computer and Programming for Game 2 | E32: 3 | F32: 1-4-4
B33: (2.2) Major Courses
B34: (2.2.1) Required Courses
B35: 958102 | D35: Introduction to Digital Games | E35: 3 | F35: 3-0-6
B36: 958201 | D36: Mathematics for Computer Graphics and Game | E36: 3
B37: 958202 | D37: Computer Graphic Programming | E37: 3
B38: 958221 | D38: Game Development 1 | E38: 3
B39: 958222 | D39: Game Development 2 | E39: 3
B40: 958225 | D40: Digital Game Production | E40: 3
...

Sheet DG2562V1.1Courses
B1: (1) General Education
B2: Course Code | C2: Course Abbrev | D2: Course Name | E2: Course Credits | F2: Credits Structure
B3: Language and Communication
B4: 001101 | C4: ENGL 101 | D4: Fundamental English 1 | E4: 3 | F4: 3-0-6
B5: 001102 | C5: ENGL 102 | D5: Fundamental English 2 | E5: 3 | F5: 3-0-6
B6: 001201 | C6: ENGL 201 | D6: Critical Reading and Effective Writing | E6: 3 | F6: 3-0-6
B7: 001229 | C7: ENGL 229 | D7: English for Media Arts | E7: 3 | F7: 3-0-6
B8: Humanities and Social Sciences
B9: 013110 | C9: PSY 100 | D9: Psychology and Daily Life | E9: 3 | F9: 3-0-6
B10: 050100 | C10: HUGE 100 | D10: Usage of The Thai Language | E10: 3 | F10: 3-0-6
B11: 109115 | C11: FAGE 115 | D11: Life and Aesthetics | E11: 3 | F11: 3-0-6
B12: 176100 | C12: LAGE 100 | D12: Law and Modern World | E12: 3 | F12: 3-0-6
B13: 703103 | C13: MGMT 103 | D13: Introduction to Enterpreneurship and Business | E13: 3 | F13: 3-0-6
B14: 751100 | C14: ECON 100 | D14: Economics for Everyday Life | E14: 3 | F14: 3-0-6
B15: 851100 | C15: MC 100 | D15: Introduction to Communication | E15: 3 | F15: 3-0-6
B17: 207110 | D17: Physics : The Science that Changed the World | E17: 3 | F17: 3-0-6
B18: 208101 | D18: Statistics for Everyday Life and Work | E18: 3 | F18: 3-0-6
B19: 801100 | D19: Architecture in Everyday Life | E19: 3 | F19: 3-0-6
B20: 953111 | D20: Software for Everyday Life | E20: 3 | F20: 3-0-6
B22: 955100 | D22: Learning through Activities 1 | E22: 1 | F22: 0-3-1
B23: 955101 | D23: Learning through Activities 2 | E23: 1 | F23: 0-3-1
B24: 057121 | D24: Football for Life and Exercise
B25: 057122 | D25: Swimming for Life and Exercise
B26: 057125 | D26: Rhythmic Activities for Life and Exercise
B27: 057126 | D27: Basketball for Life and Exercise
B28: 057127 | D28: Badminton for Life and Exercise
B29: 057128 | D29: Tennis for Life and Exercise
B30: 057129 | D30: Table Tennis for Life and Exercise
B31: 057130 | D31: Golf for Life and Exercise
B32: 057131 | D32: Exercise and Health
B33: 057133 | D33: Recreation for Quality of Life
B34: (2) Field of Specialization
B35: (2.1) Core Courses
B36: 955102 | D36: Digital Literacy | E36: 2 | F36: 1-2-3
B37: 955103 | D37: Programming and Logical Thinking | E37: 2 | F37: 1-2-3
B38: 955104 | D38: Introduction to Digital Business | E38: 2 | F38: 2-0-4
B39: 955105 | D39: Fundamental Design in Digital Arts | E39: 2 | F39: 1-2-3
B40: 958111 | D40: Computer and Programming for Game 1 | E40: 3 | F40: 1-4-4
B41: 958112 | D41: Computer and Programming for Game 2 | E41: 3 | F41: 1-4-4
B42: (2.2) Major Courses
...

Sheet สำเนาของ  เทอม 1-65
A1: ตารางเรียนสาขาวิชาดิจิทัลเกม สำหรับนักศึกษาชั้นปีที่ 3 (รหัส 62)
A2: ภาคการศึกษาที่ 2 ปีการศึกษา 2564
J3: (จำนวนนักศึกษา 47 คน)
B4: 08.00 | D4: 09.00 | F4: 10.00 | H4: 11.00 | J4: 12.00 | L4: 13.00 | N4: 14.00 | P4: 15.00 | R4: 16.00 | T4: 17.00 | V4: 18.00
A5: Monday | H5: 958371 Interactive Applications (UX UI) อ.ดร.ศุภรา B302 | L5: 958421 Advanced Game Design อ.ดร.ศุภรา 112 | O5: 958482 Sel Topic in Game Dev 2 (Shader Programming) อ.ดร.เกียรติกร C208 | R5: 958482 Sel Topic in Game Dev 2 (Shader Programming) อ.ดร.เกียรติกร C209
A9: tuesday | E9: 958372 Serious Games Design and Applications อ.ดร.กฤติยา 114 | H9: 958453 Digital Game industry and Distribution อ.ดร.ปฏิสนธิ์ (อ.พิเศษและผู้ประกอบการ) 114 | L9: 958322 Game Development 4 47 คน อ.ดร.เกียรติกร | N9: 958322 Game Development 4 /001 (C208), /002 (C209) 47 คน อ.ดร.เกียรติกร
A11: wednesday
A13: thursday | H13: 958371 Interactive Applications (UX UI) อ.ดร.ศุภรา B302 | L13: 958421 Advanced Game Design อ.ดร.ศุภรา 112
A17: Friday | E17: 958372 Serious Games Design and Applications อ.ดร.กฤติยา 114 | H17: 958453 Digital Game industry and Distribution อ.ดร.ปฏิสนธิ์ (อ.พิเศษและผู้ประกอบการ) 114 | L17: 958322 Game Development 4 47 คน อ.ดร.เกียรติกร | N17: 958322 Game Development 4 /001 (C208), /002 (C209) 47 คน อ.ดร.เกียรติกร
A21: Saturday
A22: Sunday
P23: ชื่อ อ. | Q23: อาจารย์พิเศษ | S23: เวลา | T23: ประมาณการอัตรา | V23: TA
B24: รายวิชา | K24: หน่วยกิต | L24: ผู้สอน/ผู้ดูแล | M24: ห้องเรียน | N24: วิทยากร | Q24: Lec | R24: Lab | X24: หมายเหตุ
B25: 1 | C25: 958322 | D25: Game Development 4 | K25: 3 | L25: อ.ดร.เกียรติกร | M25: C208,C209
B26: 2 | C26: 958421 | D26: Advanced Game Design | K26: 3 | L26: อ.ดร.ศุภรา | M26: 112
B27: 3 | C27: 958453 | D27: Digital Game industry and Distribution | K27: 3 | L27: อ.ดร.ปฏิสนธิ์ | M27: 114 | N27: 12 ชม. | P27: อ.อั๋น กับ บ....ทั้งวิชา | T27: 1500 / ชม.
A28: ***ให้นักศึกษาเลือกเพิ่ม | C28: เอกเลือก | K28: 6
C29: 951301 | D29: Advanced Animation and Rendering Techniques
C30: 951412 | D30: Advanced Three Dimensional Scene Design
B31: 4 | C31: 958372 | D31: Serious Games Design and Applications (อ.แจ๋ว) | L31: อ.ดร.กฤติยา | M31: 114 | N31: 3 ชม | T31: 1000/ชม | U31: ช่วง ธค 64
B32: 5 | C32: 958482 | D32: Sel Topic in Game Dev 2 (Shader Programming อ.อู๋) | L32: อ.ดร.เกียรติกร | M32: C208,C209 | N32: 3 ชม | T32: 1000/ชม | U32: ช่วง ธค 64
B33: 6 | C33: 958482 | D33: Sel Topic in Game Dev 2 (Sound) | L33: อ.เปิล
B34: 7 | C34: 958371 | D34: Interactive Applications (UX UI) (อ.มอง) | L34: อ.ดร.ศุภรา | M34: B302 | N34: 3 ชม | T34: 1000/ชม | U34: ช่วง ธค 64
B35: 8 | C35: 958333 | D35: Multiplayer Online Game Development (อ.เอม) | L35: เอม Lec Only | V35: 2 คน
B36: 9 | C36: 958451 | D36: Electronics Sports 1(อ.ก้อย) | L36: Close
B38: Free | C38: XXXXXX | D38: ---------------- | K38: 3
C39: รวม | K39: =SUM(K25:K38) -> 18
C45: ***หมายเหตุ*** สำหรับนักศึกษาที่ยังลงทะเบียนกลุ่มวิชาการเรียนรู้ผ่านกิจกรรม ไม่ครบ 3 หน่วยกิตต้องลงเพิ่มเติมให้ครบ
D47: ขาด
