Workbook

Sheet ปี1 (รหัส66) เทอม1-66
A1: ตารางเรียนสาขาวิชาดิจิทัลเกม สำหรับนักศึกษาชั้นปีที่ 1 (รหัส66)
A2: ภาคการศึกษาที่ 1 ปีการศึกษา 2567
I3: (จำนวนนักศึกษา 55 คน)
B4: 08.00 | D4: 09.00 | F4: 10.00 | H4: 11.00 | J4: 12.00 | L4: 13.00 | N4: 14.00 | P4: 15.00 | R4: 16.00 | T4: 17.00 | V4: 18.00
A5: Monday | E5: 013110 Psychology and Daily Life | H5: 001101 Fundamental English 1 | L5: 955103/lec.006 PROGRAMMING LOGICAL THINKING (113) 66 คน อ.ดร.สุมาลี | N5: 955103/lab.006 PROGRAMMING LOGICAL THINKING (c307),อ.ก้อย /lab.007(C208 ได้ห้อง C207)ขอแลกห้องกับ อ.จอห์น แล้ว TA พิเศษงบสำนักฯ sec 35,30 คน อ.ดร.สุมาลี
A7: tuesday | E7: 801100 Architecture in Everyday Life | H7: 140104 Citizenship
A11: wednesday
A13: thursday | E13: 013110 Psychology and Daily Life | H13: 001101 Fundamental English 1
A15: Friday | E15: 801100 Architecture in Everyday Life | H15: 140104 Citizenship | L15: 958111/001 COMP & PROGRAM FOR GAME 1 66 คน ผศ.ดร.กฤติยา 113 | N15: 958111/001 COMP & PROGRAM FOR GAME 1 ผศ.ดร.กฤติยา (c204), /002 TA(c206), /003 TA (c209)
A17: Saturday
A18: Sunday
Q21: วิทยากร | T21: อาจารย์พิเศษ | V21: TA | X21: ชื่ออาจารย์ | Y21: เวลา ชม./สัปดาห์ | Z21: จำนวนสัปดาห์ | AA21: สรุปค่าตอบแทน
A22: สถานนะตรวจสอบ | B22: ลำดับ | C22: รหัสวิชา | D22: รายวิชา | K22: หน่วยกิต | L22: อ.ผู้สอน | M22: ห้องเรียน | N22: หมายเหตุ | Q22: Lec (600) | R22: Lec (1000) | S22: Lec (1500) | T22: Lec (600) | U22: Lab (450) | V22: Lec (200) | W22: Lab (200)
A23: ยังไม่ได้ตรวจสอบ | B23: 1 | C23: 955103 | D23: =vlookup($C23,DG2562V1.2Courses!$B$4:$F$98,3,FALSE) -> Programming and Logical Thinking | K23: =vlookup($C23,DG2562V1.2Courses!$B$4:$F$98,4,FALSE) -> 2 | L23: อ.ดร.สุมาลี | M23: 113,c307,c208 | V23: 4
A24: ยังไม่ได้ตรวจสอบ | B24: 2 | C24: 958111 | D24: =vlookup($C24,DG2562V1.2Courses!$B$4:$F$98,3,FALSE) -> Computer and Programming for Game 1 | K24: =vlookup($C24,DG2562V1.2Courses!$B$4:$F$98,4,FALSE) -> 3 | L24: ผศ.ดร.กฤติยา | M24: 113,c204,c206,C208 | V24: 4
A25: ยังไม่ได้ตรวจสอบ | B25: 3 | C25: 013110 | D25: =vlookup($C25,DG2562V1.2Courses!$B$4:$F$98,3,FALSE) -> Psychology and Daily Life | K25: =vlookup($C25,DG2562V1.2Courses!$B$4:$F$98,4,FALSE) -> 3
A26: ยังไม่ได้ตรวจสอบ | B26: 4 | C26: 140104 | D26: =vlookup($C26,DG2562V1.2Courses!$B$4:$F$98,3,FALSE) -> Citizenship | K26: =vlookup($C26,DG2562V1.2Courses!$B$4:$F$98,4,FALSE) -> 3
A27: ยังไม่ได้ตรวจสอบ | B27: 5 | C27: 801100 | D27: =vlookup($C27,DG2562V1.2Courses!$B$4:$F$98,3,FALSE) -> Architecture in Everyday Life | K27: =vlookup($C27,DG2562V1.2Courses!$B$4:$F$98,4,FALSE) -> 3
A28: ยังไม่ได้ตรวจสอบ | B28: 6 | C28: 001101 | D28: =vlookup($C28,DG2562V1.2Courses!$B$4:$F$98,3,FALSE) -> Fundamental English 1 | K28: =vlookup($C28,DG2562V1.2Courses!$B$4:$F$98,4,FALSE) -> 3
N29: 001101 ภาษาอังกฤษ ***เวลาไม่แน่นอน*** | R29: 140104 | V29: 13110
C30: รวม | K30: =SUM(K23:K28) -> 17
N32: 001101 ภาษาอังกฤษ ***เวลาไม่แน่นอน*** | R32: 140104 | V32: 13110

Sheet ปี2 (รหัส65) เทอม1-66 (60)
A1: ตารางเรียนสาขาวิชาดิจิทัลเกม สำหรับนักศึกษาชั้นปีที่ 2 (รหัส65)
A2: ภาคการศึกษาที่ 1 ปีการศึกษา 2566
I3: (จำนวนนักศึกษา 62 คน)
B4: 08.00 | D4: 09.00 | F4: 10.00 | H4: 11.00 | J4: 12.00 | L4: 13.00 | N4: 14.00 | P4: 15.00 | R4: 16.00 | T4: 17.00 | V4: 18.00
A5: Monday | E5: 958201 MATH FOR COMP GRAPH & GAME 80 คน ผศ.ดร.กฤติยา CAMT 113 | H5: 001201 Critical Reading and Effective Writing | O5: 955104 (Sec.001) 60คน อ.ศุภรา 113
A7: tuesday | H7: 958373 GAMIFICATION 30 คน ผศ.ดร.ธีรวัฒน์ b302 (Sec001) | L7: 958225 Digital Game Production sec.001 อ.ศุภรา (อ.เอม เป็นผู้สอน) c201,c202
A9: wednesday | L9: 958261/001 GRAPHICS DESIGN FOR 2D GAMES 60คน อ.ศุภรา (อ.พิเศษ) (b302) | N9: 958261/001 อ.ศุภรา (อ.พิเศษ) GRAPHICS DESIGN FOR 2D GAMES (c207), /002 TA C208, /003ILC-C209 sec30คน
A11: thursday | E11: 958201 MATH FOR COMP GRAPH & GAME 80 คน ผศ.ดร.กฤติยา CAMT 113 | H11: 001201 Critical Reading and Effective Writing | L11: 958221/001 60คน อ.ดร.ปฏิสนธิ์ (b302) | N11: 958221/001 อ.ดร.ปฏิสนธิ์ (c204), /002 TA (c206), sec30คน
A13: Friday | H13: 958373 GAMIFICATION 30 คน ผศ.ดร.ธีรวัฒน์ b302 (Sec001)
A17: Saturday
A18: Sunday
A22: สถานนะตรวจสอบ | B22: รายวิชา | K22: หน่วยกิต | L22: ผู้สอน | M22: ห้อง | N22: หมายเหตุ | U22: วิทยากร | X22: อาจารย์พิเศษ | Z22: TA | AB22: ชื่ออาจารย์ | AC22: เวลา ชม./สัปดาห์ | AD22: จำนวนสัปดาห์ | AE22: สรุปค่าตอบแทน
A23: ยังไม่ได้ตรวจสอบ | B23: 1 | C23: 001201 | D23: =vlookup($C23,DG2562V1.2Courses!$B$4:$F$98,3,FALSE) -> Critical Reading and Effective Writing | K23: =vlookup($C23,DG2562V1.2Courses!$B$4:$F$98,4,FALSE) -> 3 | U23: Lec (600) | V23: Lec (1000) | W23: Lec (1500) | X23: Lec (600) | Y23: Lab (450) | Z23: Lec (200) | AA23: Lab (200)
A24: ยังไม่ได้ตรวจสอบ | B24: 2 | C24: 955104 | D24: =vlookup($C24,DG2562V1.2Courses!$B$4:$F$98,3,FALSE) -> Introduction to Digital Business | K24: =vlookup($C24,DG2562V1.2Courses!$B$4:$F$98,4,FALSE) -> 2
A25: ยังไม่ได้ตรวจสอบ | B25: 3 | C25: 958201 | D25: =vlookup($C25,DG2562V1.2Courses!$B$4:$F$98,3,FALSE) -> Mathematics for Computer Graphics and Game | K25: =vlookup($C25,DG2562V1.2Courses!$B$4:$F$98,4,FALSE) -> 3 | L25: ผศ.ดร.กฤติยา | M25: b302
A26: ยังไม่ได้ตรวจสอบ | B26: 4 | C26: 958221 | D26: =vlookup($C26,DG2562V1.2Courses!$B$4:$F$98,3,FALSE) -> Game Development 1 | K26: =vlookup($C26,DG2562V1.2Courses!$B$4:$F$98,4,FALSE) -> 3 | L26: อ.ดร.ปฏิสนธิ์ | M26: C207,C208 | AA26: 1(น้องมาย)
A27: ยังไม่ได้ตรวจสอบ | B27: 5 | C27: 958225 | D27: =vlookup($C27,DG2562V1.2Courses!$B$4:$F$98,3,FALSE) -> Digital Game Production | K27: =vlookup($C27,DG2562V1.2Courses!$B$4:$F$98,4,FALSE) -> 3 | L27: อ.ศุภรา (เอมสอน) | M27: c201,c202
A28: ยังไม่ได้ตรวจสอบ | B28: 6 | C28: 958261 | D28: =vlookup($C28,DG2562V1.2Courses!$B$4:$F$98,3,FALSE) -> Graphics Design for Two Dimensional Games | K28: =vlookup($C28,DG2562V1.2Courses!$B$4:$F$98,4,FALSE) -> 3 | L28: อ.ศุภรา | X28: 1 | Y28: 1
C29: เอกเลือก | K29: 3 | N29: ***ให้นักศึกษาเลือกเพิ่ม
A30: ยังไม่ได้ตรวจสอบ | B30: 7 | C30: 958373 | D30: =vlookup($C30,DG2562V1.2Courses!$B$4:$F$98,3,FALSE) -> Gamification | K30: 3 | L30: ผศ.ดร.ธีรวัฒน์ | M30: b302
A31: ยังไม่ได้ตรวจสอบ | K31: 3 | L31: อ.ดร.เทพฤทธิ์ | M31: C308 หรือ C309 | V31: 4ชม.
C32: รวม | K32: =SUM(K23:K29) -> 20
C33: ***หมายเหตุ*** สำหรับนักศึกษาที่ยังลงทะเบียนกลุ่มวิชาการเรียนรู้ผ่านกิจกรรม ไม่ครบ 3 หน่วยกิตต้องลงเพิ่มเติมให้ครบ

Sheet ปี3 (รหัส64) เทอม1-66 (58)
A1: ตารางเรียนสาขาวิชาดิจิทัลเกม สำหรับนักศึกษาชั้นปีที่ 3 (รหัส 64)
A2: ภาคการศึกษาที่ 1 ปีการศึกษา 2566
A3: (จำนวนนักศึกษา 47 คน) | G3: (จำนวนนักศึกษา 58 คน)
B4: 08.00 | D4: 09.00 | F4: 10.00 | H4: 11.00 | J4: 12.00 | L4: 13.00 | N4: 14.00 | P4: 15.00 | R4: 16.00 | T4: 17.00 | V4: 18.00
A5: Monday | E5: (เอกเลือก) 958481/sec.003 (ฺCAMT 112) Sel Topic in Game Dev1 (Basic Game Design) อ.ศุภรา lab notebook C305,C306 | L5: =C26 & "/001 " & D26 & " " & L26 & " " & M26 & " " & N26 & " คน " &O26 -> 958325/001 Artificial Intelligence for Game Development อ.ดร.ปฏิสนธิ์ C308,C309 60 คน เด็กตกแผนเพิ่มมา 13 คน (รวมใน 60 คนแล้ว)
A7: tuesday | E7: (เอกเลือก) 958481/sec.001 C308 Sel Topic in Game Dev1 (Adv UE ) อ.ดร.เทพฤทธิ์ | L7: 951212 3D Modeling and Animation Design 2 อ.ดร.กลวัชร (C204) ได้ห้อง C209 | N7: 951212 3D Modeling and Animation Design 2 อ.กลวัชร (Sec. 030, C209)
E9: (เอกเลือก) 958481/sec.004 C309 Sel Topic in Game Dev1 (Adv UE ) อ.ดร.เทพฤทธิ์
A11: wednesday | L11: 958331/sec.001 Database and Network for Game Development อ.ดร.สุมาลี lec.113 (lab C204,c206) ได้ห้อง c203/c204
A13: thursday | E13: (เอกเลือก) 958341 (ปิดกระบวนวิชานี้) แล้วเปิดกระบวนวิชา 958481 (ตอนที่ 002) Realistic Game Sel Topic in Game prog patterns Development อ.ดร.เกียรติกร (C309) | L13: =C25 & "/sec.001 " & D25 & " " &L25 & " " & N25 & " คน " & M25 & " " & O25 -> 958321/sec.001 Game Development 3 อ.ดร.เกียรติกร 58 คน C308,C309,307 เด็กตกแผนเพิ่มมา 13 คน | N13: 958321/001 (C307) Game Development 3 อ.ดร.เกียรติกร Sec.002/(C308), TA Sec.003 (C309),อานน Sec 25 คน
B15: (เอกเลือก) 958441 Motion Capture for Game Development ผศ.ดร.ธีรวัฒน์ (112) | D15: (เอกเลือก) 958441 LAB / 001 (จำนวนที่รองรับได้ 30 คน) Motion Capture for Game Development ผศ.ดร.ธีรวัฒน์ (C202) แลกห้องกับ อ.แนท SE เป็นห้อง C206 เรียบร้อยแล้ว
A17: Friday | L17: (เอกเลือก) 958481 (ฺB302) Sel Topic in Game Dev1 (Basic Game Design) อ.ศุภรา
A19: Saturday
A20: Sunday
S23: วิทยากร | V23: อาจารย์พิเศษ | X23: TA | Z23: ชื่ออาจารย์ | AA23: เวลา ชม./สัปดาห์ | AB23: จำนวนสัปดาห์ | AC23: สรุปค่าตอบแทน
A24: สถานนะตรวจสอบ | D24: เอกบังคับ | E24: รายวิชา | L24: ผู้สอน | M24: ห้อง | N24: จำนวนรับ Sec001 | O24: หมายเหตุ | S24: Lec (600) | T24: Lec (1000) | U24: Lec (1500) | V24: Lec (600) | W24: Lab (450) | X24: Lec (200) | Y24: Lab (200)
A25: ยังไม่ได้ตรวจสอบ | B25: 1 | C25: 958321 | D25: Game Development 3 | J25: 3 | K25: 001 | L25: อ.ดร.เกียรติกร | M25: C308,C309,307 | N25: 58 | O25: เด็กตกแผนเพิ่มมา 13 คน
A26: ยังไม่ได้ตรวจสอบ | B26: 2 | C26: 958325 | D26: Artificial Intelligence for Game Development | J26: 3 | K26: 001 | L26: อ.ดร.ปฏิสนธิ์ | M26: C308,C309 | N26: =47+13 -> 60 | O26: เด็กตกแผนเพิ่มมา 13 คน (รวมใน 60 คนแล้ว)
A27: ยังไม่ได้ตรวจสอบ | B27: 3 | C27: 958331 | D27: Database and Network for Game Development | J27: 3 | K27: 001 | L27: อ.ดร. สุมาลี | M27: C206,C207 | N27: 60 (ห้องรับได้ถึง 68) | O27: เด็กตกแผนเพิ่มมา 13 คน (รวมใน 60 คนแล้ว) | T27: 1คน 3ชม.
B28: ***ให้นักศึกษาเลือกเพิ่ม | D28: เอกเลือก | J28: 6
A29: ยังไม่ได้ตรวจสอบ | C29: 958341 | D29: Realistic Game Development (เอกเลือก) | J29: 3 | K29: 001 | L29: อ.ดร.เกียรติกร | M29: C309 | N29: 30 | O29: ปิดกระบวนวิชา
A30: ยังไม่ได้ตรวจสอบ | B30: 4 | C30: 958481 | J30: 3 | K30: 002 | L30: อ.ดร.เกียรติกร | M30: C309 | N30: 30 | O30: เปิดกระบวนวิชานี้แทน
A31: ยังไม่ได้ตรวจสอบ | B31: 5 | C31: 958441 | D31: Motion Capture for Game Development(เอกเลือก) | J31: 3 | K31: 001 | L31: ผศ.ดร.ธีรวัฒน์ | M31: 112 ,C202,C206 | N31: 30 | T31: 1คน 10ชม.(2ครั้ง)
A32: ตรวจสอบแล้ว (เทพฤทธิ์) | B32: 6 | C32: 958481 | D32: Sel Topic in Game Dev1 (AdvUE + VR) | J32: 3 | K32: 001 | L32: อ.ดร.เทพฤทธิ์ | M32: XXX | N32: 25
A33: ยังไม่ได้ตรวจสอบ | B33: 7 | C33: 958481 | D33: Sel Topic in Game Dev1 (Basic Game Design) (เอกเลือก) | J33: 3 | K33: 003 | L33: อ.ศุภรา | M33: B302 | N33: 59 | X33: 1(น้องยู้)
A34: ยังไม่ได้ตรวจสอบ | B34: 8 | C34: 951212 | D34: Three Dimensional Modeling and Animation Design 2 | J34: 3 | K34: 001 | L34: อ.ดร.อรุษ | M34: C208 | N34: 25
C35: รวม | J35: =SUM(J25:J28) -> 15
C36: ***หมายเหตุ*** สำหรับนักศึกษาที่ยังลงทะเบียนกลุ่มวิชาการเรียนรู้ผ่านกิจกรรม ไม่ครบ 3 หน่วยกิตต้องลงเพิ่มเติมให้ครบ
C43: test | D43: =C25 & " " & D25 -> 958321 Game Development 3

Sheet ปี4 (รหัส63) เทอม1-66 (45)
A1: ตารางเรียนสาขาวิชาดิจิทัลเกม สำหรับนักศึกษาชั้นปีที่ 4 (รหัส63)
A2: ภาคการศึกษาที่ 1 ปีการศึกษา 2566
A3: (จำนวนนักศึกษา 45 คน)
B4: 08.00 | D4: 09.00 | F4: 10.00 | H4: 11.00 | J4: 12.00 | L4: 13.00 | N4: 14.00 | P4: 15.00 | R4: 16.00 | T4: 17.00 | V4: 18.00
A5: Monday
A7: tuesday
A9: wednesday
A11: thursday | L11: =C23 & "/001 " & D23 & " " &L23 & " " & N23 & " คน " -> 958491/001 Work integrated Lerning for Digital Game 1 อ. เกียรติกร 45 คน
A15: Friday
A17: Saturday
A18: Sunday
B21: Section | R21: วิทยากร | U21: อาจารย์พิเศษ | W21: TA | Y21: ชื่ออาจารย์ | Z21: เวลา ชม./สัปดาห์ | AA21: จำนวนสัปดาห์ | AB21: สรุปค่าตอบแทน
B22: รายวิชา | K22: หน่วยกิต | L22: ผู้สอน | M22: ห้อง | N22: คน | O22: หมายเหตุ | R22: Lec (600) | S22: Lec (1000) | T22: Lec (1500) | U22: Lec (600) | V22: Lab (450) | W22: Lec (200) | X22: Lab (200)
B23: 1 | C23: 958491 | D23: Work integrated Lerning for Digital Game 1 | K23: 9 | L23: อ. เกียรติกร | N23: 45
B24: 2 | C24: 958491 | L24: อ. เอ๋
B25: 3 | C25: 958491 | L25: อ. แจ๋ว
B26: 4 | C26: 958491 | L26: อ. น้อย
B27: 5 | C27: 958491 | L27: อ. จอน
B28: 6 | C28: 958491 | L28: อ. จูน
B29: 7 | C29: 958491 | L29: อ. สุมาลี
B30: 8 | C30: 958491 | L30: อ. มอง
C33: รวม | K33: =SUM(K23:K32) -> 9
C34: ***หมายเหตุ*** สำหรับนักศึกษาที่ยังลงทะเบียนกลุ่มวิชาการเรียนรู้ผ่านกิจกรรม ไม่ครบ 3 หน่วยกิตต้องลงเพิ่มเติมให้ครบ

Sheet DG2562V1.1Courses
B1: (1) General Education
B2: Course Code | C2: Course Abbrev | D2: Course Name | E2: Course Credits | F2: Credits Structure
B3: Language and Communication
B4: 001101 | C4: ENGL 101 | D4: Fundamental English 1 | E4: 3 | F4: 3-0-6
B5: 001102 | C5: ENGL 102 | D5: Fundamental English 2 | E5: 3 | F5: 3-0-6
B6: 001201 | C6: ENGL 201 | D6: Critical Reading and Effective Writing | E6: 3 | F6: 3-0-6
B7: 001229 | C7: ENGL 229 | D7: English for Media Arts | E7: 3 | F7: 3-0-6
B8: Humanities and Social Sciences
B9: 013110 | C9: PSY 100 | D9: Psychology and Daily Life | E9: 3 | F9: 3-0-6
B10: 050100 | C10: HUGE 100 | D10: Usage of The Thai Language | E10: 3 | F10: 3-0-6
B11: 109115 | C11: FAGE 115 | D11: Life and Aesthetics | E11: 3 | F11: 3-0-6
B12: 176100 | C12: LAGE 100 | D12: Law and Modern World | E12: 3 | F12: 3-0-6
B13: 703103 | C13: MGMT 103 | D13: Introduction to Enterpreneurship and Business | E13: 3 | F13: 3-0-6
B14: 751100 | C14: ECON 100 | D14: Economics for Everyday Life | E14: 3 | F14: 3-0-6
B15: 851100 | C15: MC 100 | D15: Introduction to Communication | E15: 3 | F15: 3-0-6
B17: 207110 | D17: Physics : The Science that Changed the World | E17: 3 | F17: 3-0-6
B18: 208101 | D18: Statistics for Everyday Life and Work | E18: 3 | F18: 3-0-6
B19: 801100 | D19: Architecture in Everyday Life | E19: 3 | F19: 3-0-6
B20: 953111 | D20: Software for Everyday Life | E20: 3 | F20: 3-0-6
B22: 955100 | D22: Learning through Activities 1 | E22: 1 | F22: 0-3-1
B23: 955101 | D23: Learning through Activities 2 | E23: 1 | F23: 0-3-1
B24: 057121 | D24: Football for Life and Exercise
B25: 057122 | D25: Swimming for Life and Exercise
B26: 057125 | D26: Rhythmic Activities for Life and Exercise
B27: 057126 | D27: Basketball for Life and Exercise
B28: 057127 | D28: Badminton for Life and Exercise
B29: 057128 | D29: Tennis for Life and Exercise
B30: 057129 | D30: Table Tennis for Life and Exercise
B31: 057130 | D31: Golf for Life and Exercise
B32: 057131 | D32: Exercise and Health
B33: 057133 | D33: Recreation for Quality of Life
B34: (2) Field of Specialization
B35: (2.1) Core Courses
B36: 955102 | D36: Digital Literacy | E36: 2 | F36: 1-2-3
B37: 955103 | D37: Programming and Logical Thinking | E37: 2 | F37: 1-2-3
B38: 955104 | D38: Introduction to Digital Business | E38: 2 | F38: 2-0-4
B39: 955105 | D39: Fundamental Design in Digital Arts | E39: 2 | F39: 1-2-3
B40: 958111 | D40: Computer and Programming for Game 1 | E40: 3 | F40: 1-4-4
B41: 958112 | D41: Computer and Programming for Game 2 | E41: 3 | F41: 1-4-4
B42: (2.2) Major Courses
...

Sheet DG2562V1.2Courses
B1: (1) General Education
B2: Course Code | C2: Course Abbrev | D2: Course Name | E2: Course Credits | F2: Credits Structure
B3: 1.1 Required Courses
B4: 001101 | C4: ENGL 101 | D4: Fundamental English 1 | E4: 3 | F4: 3-0-6
B5: 001102 | C5: ENGL 102 | D5: Fundamental English 2 | E5: 3 | F5: 3-0-6
B6: 001201 | C6: ENGL 201 | D6: Critical Reading and Effective Writing | E6: 3 | F6: 3-0-6
B7: 001229 | C7: ENGL 229 | D7: English for Media Arts | E7: 3 | F7: 3-0-6
B8: 261111 | D8: Internet and Online Community | E8: 3
B9: 1.2 Innovative Co-Creator
B10: 013110 | C10: PSY 100 | D10: Psychology and Daily Life | E10: 3 | F10: 3-0-6
B11: 206100 | D11: Mathematics in Everyday Life | E11: 3
B12: 356102 | D12: Ornamental Aquatic Animals | E12: 3
B13: 852100 | D13: Introduction to Film | E13: 3
B14: 888107 | D14: Business Startup on Digital Platform | E14: 3
B15: 1.3 Active Citizen
B16: 140104 | D16: Citizenship | E16: 3
B17: 1.4 Elective Courses
B18: 057137 | D18: Sports for Health | E18: 3
B19: 011155 | D19: Philosophy of Happiness | E19: 3
B20: 011100 | D20: Man and Philosophy | E20: 3
B21: 012200 | D21: Mind Volunteer | E21: 3
B22: 154100 | D22: Introduction to Geography | E22: 3
B23: 259108 | D23: Electricity in Everyday Life | E23: 3
B24: 801100 | D24: Architecture in Everyday Life | E24: 3
B25: (2) Field of Specialization
B26: (2.1) Core Courses
B27: 955102 | D27: Digital Literacy | E27: 2 | F27: 1-2-3
B28: 955103 | D28: Programming and Logical Thinking | E28: 2 | F28: 1-2-3
B29: 955104 | D29: Introduction to Digital Business | E29: 2 | F29: 2-0-4
B30: 955105 | D30: Fundamental Design in Digital Arts | E30: 2 | F30: 1-2-3
B31: 958111 | D31: Computer and Programming for Game 1 | E31: 3 | F31: 1-4-4
B32: 958112 | D32: Computer and Programming for Game 2 | E32: 3 | F32: 1-4-4
B33: (2.2) Major Courses
B34: (2.2.1) Required Courses
B35: 958201 | D35: Mathematics for Computer Graphics and Game | E35: 3
B36: 958202 | D36: Computer Graphic Programming | E36: 3
B37: 958221 | D37: Game Development 1 | E37: 3
B38: 958222 | D38: Game Development 2 | E38: 3
B39: 958225 | D39: Digital Game Production | E39: 3
B40: 958261 | D40: Graphics Design for Two Dimensional Games | E40: 3
...

Sheet Workload
B3: เทอม1 | C3: วิชา
A4: อ.อู๋ | B4: 2
A5: อ.เอม | B5: 2
A6: อ.มอง | B6: 2
A7: อ.เเจ๋ว | B7: 2
A8: อ.น้อย | B8: 2
A9: อ.ก้อย | B9: 2
A10: อ.จอห์น | B10: เกิน 2
A11: อ.เอ๋ | B11: 2

Sheet สำเนาของ  เทอม 1-65
A1: ตารางเรียนสาขาวิชาดิจิทัลเกม สำหรับนักศึกษาชั้นปีที่ 3 (รหัส 62)
A2: ภาคการศึกษาที่ 2 ปีการศึกษา 2564
J3: (จำนวนนักศึกษา 47 คน)
B4: 08.00 | D4: 09.00 | F4: 10.00 | H4: 11.00 | J4: 12.00 | L4: 13.00 | N4: 14.00 | P4: 15.00 | R4: 16.00 | T4: 17.00 | V4: 18.00
A5: Monday | H5: 958371 Interactive Applications (UX UI) อ.ดร.ศุภรา B302 | L5: 958421 Advanced Game Design อ.ดร.ศุภรา 112 | O5: 958482 Sel Topic in Game Dev 2 (Shader Programming) อ.ดร.เกียรติกร C208 | R5: 958482 Sel Topic in Game Dev 2 (Shader Programming) อ.ดร.เกียรติกร C209
A9: tuesday | E9: 958372 Serious Games Design and Applications อ.ดร.กฤติยา 114 | H9: 958453 Digital Game industry and Distribution อ.ดร.ปฏิสนธิ์ (อ.พิเศษและผู้ประกอบการ) 114 | L9: 958322 Game Development 4 47 คน อ.ดร.เกียรติกร | N9: 958322 Game Development 4 /001 (C208), /002 (C209) 47 คน อ.ดร.เกียรติกร
A11: wednesday
A13: thursday | H13: 958371 Interactive Applications (UX UI) อ.ดร.ศุภรา B302 | L13: 958421 Advanced Game Design อ.ดร.ศุภรา 112
A17: Friday | E17: 958372 Serious Games Design and Applications อ.ดร.กฤติยา 114 | H17: 958453 Digital Game industry and Distribution อ.ดร.ปฏิสนธิ์ (อ.พิเศษและผู้ประกอบการ) 114 | L17: 958322 Game Development 4 47 คน อ.ดร.เกียรติกร | N17: 958322 Game Development 4 /001 (C208), /002 (C209) 47 คน อ.ดร.เกียรติกร
A21: Saturday
A22: Sunday
P23: ชื่อ อ. | Q23: อาจารย์พิเศษ | S23: เวลา | T23: ประมาณการอัตรา | V23: TA
B24: รายวิชา | K24: หน่วยกิต | L24: ผู้สอน/ผู้ดูแล | M24: ห้องเรียน | N24: วิทยากร | Q24: Lec | R24: Lab | X24: หมายเหตุ
B25: 1 | C25: 958322 | D25: Game Development 4 | K25: 3 | L25: อ.ดร.เกียรติกร | M25: C208,C209
B26: 2 | C26: 958421 | D26: Advanced Game Design | K26: 3 | L26: อ.ดร.ศุภรา | M26: 112
B27: 3 | C27: 958453 | D27: Digital Game industry and Distribution | K27: 3 | L27: อ.ดร.ปฏิสนธิ์ | M27: 114 | N27: 12 ชม. | P27: อ.อั๋น กับ บ....ทั้งวิชา | T27: 1500 / ชม.
A28: ***ให้นักศึกษาเลือกเพิ่ม | C28: เอกเลือก | K28: 6
C29: 951301 | D29: Advanced Animation and Rendering Techniques
C30: 951412 | D30: Advanced Three Dimensional Scene Design
B31: 4 | C31: 958372 | D31: Serious Games Design and Applications (อ.แจ๋ว) | L31: อ.ดร.กฤติยา | M31: 114 | N31: 3 ชม | T31: 1000/ชม | U31: ช่วง ธค 64
B32: 5 | C32: 958482 | D32: Sel Topic in Game Dev 2 (Shader Programming อ.อู๋) | L32: อ.ดร.เกียรติกร | M32: C208,C209 | N32: 3 ชม | T32: 1000/ชม | U32: ช่วง ธค 64
B33: 6 | C33: 958482 | D33: Sel Topic in Game Dev 2 (Sound) | L33: อ.เปิล
B34: 7 | C34: 958371 | D34: Interactive Applications (UX UI) (อ.มอง) | L34: อ.ดร.ศุภรา | M34: B302 | N34: 3 ชม | T34: 1000/ชม | U34: ช่วง ธค 64
B35: 8 | C35: 958333 | D35: Multiplayer Online Game Development (อ.เอม) | L35: เอม Lec Only | V35: 2 คน
B36: 9 | C36: 958451 | D36: Electronics Sports 1(อ.ก้อย) | L36: Close
B38: Free | C38: XXXXXX | D38: ---------------- | K38: 3
C39: รวม | K39: =SUM(K25:K38) -> 18
C45: ***หมายเหตุ*** สำหรับนักศึกษาที่ยังลงทะเบียนกลุ่มวิชาการเรียนรู้ผ่านกิจกรรม ไม่ครบ 3 หน่วยกิตต้องลงเพิ่มเติมให้ครบ
D47: ขาด
